Workbook

Sheet Fixture
A1: ID_Partido | B1: Fecha | C1: Fase | D1: Grupo | E1: Equipo_A | F1: Equipo_B | G1: Estadio | H1: Ciudad | I1: Pais_Sede | J1: Localia_A | K1: Localia_B | L1: Num_FIFA
A2: 1 | B2: 2026-06-11 | C2: Grupos | D2: A | E2: México | F2: Sudáfrica | H2: Mexico City | I2: México | J2: =IF(OR(AND($E2="México",$I2="México"),AND($E2="Estados Unidos",$I2="Estados Unidos"),AND($E2="Canadá",$I2="Canadá")),1,0) | K2: =IF(OR(AND($F2="México",$I2="México"),AND($F2="Estados Unidos",$I2="Estados Unidos"),AND($F2="Canadá",$I2="Canadá")),1,0)
A3: 2 | B3: 2026-06-11 | C3: Grupos | D3: A | E3: Corea del Sur | F3: Chequia | H3: Guadalajara (Zapopan) | I3: México | J3: =IF(OR(AND($E3="México",$I3="México"),AND($E3="Estados Unidos",$I3="Estados Unidos"),AND($E3="Canadá",$I3="Canadá")),1,0) | K3: =IF(OR(AND($F3="México",$I3="México"),AND($F3="Estados Unidos",$I3="Estados Unidos"),AND($F3="Canadá",$I3="Canadá")),1,0)
A4: 3 | B4: 2026-06-12 | C4: Grupos | D4: B | E4: Canadá | F4: Bosnia y Herzegovina | H4: Toronto | I4: Canadá | J4: =IF(OR(AND($E4="México",$I4="México"),AND($E4="Estados Unidos",$I4="Estados Unidos"),AND($E4="Canadá",$I4="Canadá")),1,0) | K4: =IF(OR(AND($F4="México",$I4="México"),AND($F4="Estados Unidos",$I4="Estados Unidos"),AND($F4="Canadá",$I4="Canadá")),1,0)
A5: 4 | B5: 2026-06-12 | C5: Grupos | D5: D | E5: Estados Unidos | F5: Paraguay | H5: Los Angeles (Inglewood) | I5: Estados Unidos | J5: =IF(OR(AND($E5="México",$I5="México"),AND($E5="Estados Unidos",$I5="Estados Unidos"),AND($E5="Canadá",$I5="Canadá")),1,0) | K5: =IF(OR(AND($F5="México",$I5="México"),AND($F5="Estados Unidos",$I5="Estados Unidos"),AND($F5="Canadá",$I5="Canadá")),1,0)
A6: 5 | B6: 2026-06-13 | C6: Grupos | D6: B | E6: Qatar | F6: Suiza | H6: San Francisco Bay Area (Santa Clara) | I6: Estados Unidos | J6: =IF(OR(AND($E6="México",$I6="México"),AND($E6="Estados Unidos",$I6="Estados Unidos"),AND($E6="Canadá",$I6="Canadá")),1,0) | K6: =IF(OR(AND($F6="México",$I6="México"),AND($F6="Estados Unidos",$I6="Estados Unidos"),AND($F6="Canadá",$I6="Canadá")),1,0)
A7: 6 | B7: 2026-06-13 | C7: Grupos | D7: C | E7: Brasil | F7: Marruecos | H7: New York/New Jersey (East Rutherford) | I7: Estados Unidos | J7: =IF(OR(AND($E7="México",$I7="México"),AND($E7="Estados Unidos",$I7="Estados Unidos"),AND($E7="Canadá",$I7="Canadá")),1,0) | K7: =IF(OR(AND($F7="México",$I7="México"),AND($F7="Estados Unidos",$I7="Estados Unidos"),AND($F7="Canadá",$I7="Canadá")),1,0)
A8: 7 | B8: 2026-06-13 | C8: Grupos | D8: C | E8: Haití | F8: Escocia | H8: Boston (Foxborough) | I8: Estados Unidos | J8: =IF(OR(AND($E8="México",$I8="México"),AND($E8="Estados Unidos",$I8="Estados Unidos"),AND($E8="Canadá",$I8="Canadá")),1,0) | K8: =IF(OR(AND($F8="México",$I8="México"),AND($F8="Estados Unidos",$I8="Estados Unidos"),AND($F8="Canadá",$I8="Canadá")),1,0)
A9: 8 | B9: 2026-06-13 | C9: Grupos | D9: D | E9: Australia | F9: Turquía | H9: Vancouver | I9: Canadá | J9: =IF(OR(AND($E9="México",$I9="México"),AND($E9="Estados Unidos",$I9="Estados Unidos"),AND($E9="Canadá",$I9="Canadá")),1,0) | K9: =IF(OR(AND($F9="México",$I9="México"),AND($F9="Estados Unidos",$I9="Estados Unidos"),AND($F9="Canadá",$I9="Canadá")),1,0)
A10: 9 | B10: 2026-06-14 | C10: Grupos | D10: E | E10: Alemania | F10: Curaçao | H10: Houston | I10: Estados Unidos | J10: =IF(OR(AND($E10="México",$I10="México"),AND($E10="Estados Unidos",$I10="Estados Unidos"),AND($E10="Canadá",$I10="Canadá")),1,0) | K10: =IF(OR(AND($F10="México",$I10="México"),AND($F10="Estados Unidos",$I10="Estados Unidos"),AND($F10="Canadá",$I10="Canadá")),1,0)
A11: 10 | B11: 2026-06-14 | C11: Grupos | D11: F | E11: Países Bajos | F11: Japón | H11: Dallas (Arlington) | I11: Estados Unidos | J11: =IF(OR(AND($E11="México",$I11="México"),AND($E11="Estados Unidos",$I11="Estados Unidos"),AND($E11="Canadá",$I11="Canadá")),1,0) | K11: =IF(OR(AND($F11="México",$I11="México"),AND($F11="Estados Unidos",$I11="Estados Unidos"),AND($F11="Canadá",$I11="Canadá")),1,0)
A12: 11 | B12: 2026-06-14 | C12: Grupos | D12: E | E12: Costa de Marfil | F12: Ecuador | H12: Philadelphia | I12: Estados Unidos | J12: =IF(OR(AND($E12="México",$I12="México"),AND($E12="Estados Unidos",$I12="Estados Unidos"),AND($E12="Canadá",$I12="Canadá")),1,0) | K12: =IF(OR(AND($F12="México",$I12="México"),AND($F12="Estados Unidos",$I12="Estados Unidos"),AND($F12="Canadá",$I12="Canadá")),1,0)
A13: 12 | B13: 2026-06-14 | C13: Grupos | D13: F | E13: Suecia | F13: Túnez | H13: Monterrey (Guadalupe) | I13: México | J13: =IF(OR(AND($E13="México",$I13="México"),AND($E13="Estados Unidos",$I13="Estados Unidos"),AND($E13="Canadá",$I13="Canadá")),1,0) | K13: =IF(OR(AND($F13="México",$I13="México"),AND($F13="Estados Unidos",$I13="Estados Unidos"),AND($F13="Canadá",$I13="Canadá")),1,0)
... A73: 72 | B73: 2026-06-27 | C73: Grupos | D73: J | E73: Jordania | F73: Argentina | H73: Dallas (Arlington) | I73: Estados Unidos | J73: =IF(OR(AND($E73="México",$I73="México"),AND($E73="Estados Unidos",$I73="Estados Unidos"),AND($E73="Canadá",$I73="Canadá")),1,0) | K73: =IF(OR(AND($F73="México",$I73="México"),AND($F73="Estados Unidos",$I73="Estados Unidos"),AND($F73="Canadá",$I73="Canadá")),1,0)
A74: 73 | B74: 2026-06-28 | C74: R32 | E74: 2A | F74: 2B | H74: Los Angeles (Inglewood) | I74: Estados Unidos | J74: =IF(OR(AND($E74="México",$I74="México"),AND($E74="Estados Unidos",$I74="Estados Unidos"),AND($E74="Canadá",$I74="Canadá")),1,0) | K74: =IF(OR(AND($F74="México",$I74="México"),AND($F74="Estados Unidos",$I74="Estados Unidos"),AND($F74="Canadá",$I74="Canadá")),1,0) | L74: 73
A75: 74 | B75: 2026-06-29 | C75: R32 | E75: 1C | F75: 2F | H75: Houston | I75: Estados Unidos | J75: =IF(OR(AND($E75="México",$I75="México"),AND($E75="Estados Unidos",$I75="Estados Unidos"),AND($E75="Canadá",$I75="Canadá")),1,0) | K75: =IF(OR(AND($F75="México",$I75="México"),AND($F75="Estados Unidos",$I75="Estados Unidos"),AND($F75="Canadá",$I75="Canadá")),1,0) | L75: 76
A76: 75 | B76: 2026-06-29 | C76: R32 | E76: 1E | F76: 3A/B/C/D/F | H76: Boston (Foxborough) | I76: Estados Unidos | J76: =IF(OR(AND($E76="México",$I76="México"),AND($E76="Estados Unidos",$I76="Estados Unidos"),AND($E76="Canadá",$I76="Canadá")),1,0) | K76: =IF(OR(AND($F76="México",$I76="México"),AND($F76="Estados Unidos",$I76="Estados Unidos"),AND($F76="Canadá",$I76="Canadá")),1,0) | L76: 74
A77: 76 | B77: 2026-06-29 | C77: R32 | E77: 1F | F77: 2C | H77: Monterrey (Guadalupe) | I77: México | J77: =IF(OR(AND($E77="México",$I77="México"),AND($E77="Estados Unidos",$I77="Estados Unidos"),AND($E77="Canadá",$I77="Canadá")),1,0) | K77: =IF(OR(AND($F77="México",$I77="México"),AND($F77="Estados Unidos",$I77="Estados Unidos"),AND($F77="Canadá",$I77="Canadá")),1,0) | L77: 75
A78: 77 | B78: 2026-06-30 | C78: R32 | E78: 2E | F78: 2I | H78: Dallas (Arlington) | I78: Estados Unidos | J78: =IF(OR(AND($E78="México",$I78="México"),AND($E78="Estados Unidos",$I78="Estados Unidos"),AND($E78="Canadá",$I78="Canadá")),1,0) | K78: =IF(OR(AND($F78="México",$I78="México"),AND($F78="Estados Unidos",$I78="Estados Unidos"),AND($F78="Canadá",$I78="Canadá")),1,0) | L78: 78
A79: 78 | B79: 2026-06-30 | C79: R32 | E79: 1I | F79: 3C/D/F/G/H | H79: New York/New Jersey (East Rutherford) | I79: Estados Unidos | J79: =IF(OR(AND($E79="México",$I79="México"),AND($E79="Estados Unidos",$I79="Estados Unidos"),AND($E79="Canadá",$I79="Canadá")),1,0) | K79: =IF(OR(AND($F79="México",$I79="México"),AND($F79="Estados Unidos",$I79="Estados Unidos"),AND($F79="Canadá",$I79="Canadá")),1,0) | L79: 77
A80: 79 | B80: 2026-06-30 | C80: R32 | E80: 1A | F80: 3C/E/F/H/I | H80: Mexico City | I80: México | J80: =IF(OR(AND($E80="México",$I80="México"),AND($E80="Estados Unidos",$I80="Estados Unidos"),AND($E80="Canadá",$I80="Canadá")),1,0) | K80: =IF(OR(AND($F80="México",$I80="México"),AND($F80="Estados Unidos",$I80="Estados Unidos"),AND($F80="Canadá",$I80="Canadá")),1,0) | L80: 79
A81: 80 | B81: 2026-07-01 | C81: R32 | E81: 1L | F81: 3E/H/I/J/K | H81: Atlanta | I81: Estados Unidos | J81: =IF(OR(AND($E81="México",$I81="México"),AND($E81="Estados Unidos",$I81="Estados Unidos"),AND($E81="Canadá",$I81="Canadá")),1,0) | K81: =IF(OR(AND($F81="México",$I81="México"),AND($F81="Estados Unidos",$I81="Estados Unidos"),AND($F81="Canadá",$I81="Canadá")),1,0) | L81: 80
A82: 81 | B82: 2026-07-01 | C82: R32 | E82: 1G | F82: 3A/E/H/I/J | H82: Seattle | I82: Estados Unidos | J82: =IF(OR(AND($E82="México",$I82="México"),AND($E82="Estados Unidos",$I82="Estados Unidos"),AND($E82="Canadá",$I82="Canadá")),1,0) | K82: =IF(OR(AND($F82="México",$I82="México"),AND($F82="Estados Unidos",$I82="Estados Unidos"),AND($F82="Canadá",$I82="Canadá")),1,0) | L82: 82
A83: 82 | B83: 2026-07-01 | C83: R32 | E83: 1D | F83: 3B/E/F/I/J | H83: San Francisco Bay Area (Santa Clara) | I83: Estados Unidos | J83: =IF(OR(AND($E83="México",$I83="México"),AND($E83="Estados Unidos",$I83="Estados Unidos"),AND($E83="Canadá",$I83="Canadá")),1,0) | K83: =IF(OR(AND($F83="México",$I83="México"),AND($F83="Estados Unidos",$I83="Estados Unidos"),AND($F83="Canadá",$I83="Canadá")),1,0) | L83: 81
A84: 83 | B84: 2026-07-02 | C84: R32 | E84: 1H | F84: 2J | H84: Los Angeles (Inglewood) | I84: Estados Unidos | J84: =IF(OR(AND($E84="México",$I84="México"),AND($E84="Estados Unidos",$I84="Estados Unidos"),AND($E84="Canadá",$I84="Canadá")),1,0) | K84: =IF(OR(AND($F84="México",$I84="México"),AND($F84="Estados Unidos",$I84="Estados Unidos"),AND($F84="Canadá",$I84="Canadá")),1,0) | L84: 84
A85: 84 | B85: 2026-07-02 | C85: R32 | E85: 2K | F85: 2L | H85: Toronto | I85: Canadá | J85: =IF(OR(AND($E85="México",$I85="México"),AND($E85="Estados Unidos",$I85="Estados Unidos"),AND($E85="Canadá",$I85="Canadá")),1,0) | K85: =IF(OR(AND($F85="México",$I85="México"),AND($F85="Estados Unidos",$I85="Estados Unidos"),AND($F85="Canadá",$I85="Canadá")),1,0) | L85: 83
... A105: 104 | B105: 2026-07-19 | C105: Final | E105: W101 | F105: W102 | H105: New York/New Jersey (East Rutherford) | I105: Estados Unidos | J105: =IF(OR(AND($E105="México",$I105="México"),AND($E105="Estados Unidos",$I105="Estados Unidos"),AND($E105="Canadá",$I105="Canadá")),1,0) | K105: =IF(OR(AND($F105="México",$I105="México"),AND($F105="Estados Unidos",$I105="Estados Unidos"),AND($F105="Canadá",$I105="Canadá")),1,0) | L105: 104

Sheet Resultados
A1: ID_Partido | B1: Goles_A | C1: Goles_B | D1: Definido_Por | E1: Ganador_Penales | F1: Equipo_A (ref) | G1: Equipo_B (ref)
A2: 1 | B2: 2 | C2: 0 | D2: 90 | F2: =VLOOKUP($A2,Fixture!$A:$F,5,0) | G2: =VLOOKUP($A2,Fixture!$A:$F,6,0)
A3: 2 | B3: 2 | C3: 1 | D3: 90 | F3: =VLOOKUP($A3,Fixture!$A:$F,5,0) | G3: =VLOOKUP($A3,Fixture!$A:$F,6,0)
A4: 3 | B4: 1 | C4: 1 | D4: 90 | F4: =VLOOKUP($A4,Fixture!$A:$F,5,0) | G4: =VLOOKUP($A4,Fixture!$A:$F,6,0)
A5: 4 | B5: 4 | C5: 1 | D5: 90 | F5: =VLOOKUP($A5,Fixture!$A:$F,5,0) | G5: =VLOOKUP($A5,Fixture!$A:$F,6,0)
A6: 5 | B6: 1 | C6: 1 | D6: 90 | F6: =VLOOKUP($A6,Fixture!$A:$F,5,0) | G6: =VLOOKUP($A6,Fixture!$A:$F,6,0)
A7: 6 | B7: 1 | C7: 1 | D7: 90 | F7: =VLOOKUP($A7,Fixture!$A:$F,5,0) | G7: =VLOOKUP($A7,Fixture!$A:$F,6,0)
A8: 7 | B8: 0 | C8: 1 | D8: 90 | F8: =VLOOKUP($A8,Fixture!$A:$F,5,0) | G8: =VLOOKUP($A8,Fixture!$A:$F,6,0)
A9: 8 | B9: 2 | C9: 0 | D9: 90 | F9: =VLOOKUP($A9,Fixture!$A:$F,5,0) | G9: =VLOOKUP($A9,Fixture!$A:$F,6,0)
A10: 9 | B10: 7 | C10: 1 | D10: 90 | F10: =VLOOKUP($A10,Fixture!$A:$F,5,0) | G10: =VLOOKUP($A10,Fixture!$A:$F,6,0)
A11: 10 | B11: 2 | C11: 2 | D11: 90 | F11: =VLOOKUP($A11,Fixture!$A:$F,5,0) | G11: =VLOOKUP($A11,Fixture!$A:$F,6,0)
A12: 11 | B12: 1 | C12: 0 | D12: 90 | F12: =VLOOKUP($A12,Fixture!$A:$F,5,0) | G12: =VLOOKUP($A12,Fixture!$A:$F,6,0)
A13: 12 | B13: 5 | C13: 1 | D13: 90 | F13: =VLOOKUP($A13,Fixture!$A:$F,5,0) | G13: =VLOOKUP($A13,Fixture!$A:$F,6,0)
... A73: 72 | B73: 1 | C73: 3 | D73: 90 | F73: =VLOOKUP($A73,Fixture!$A:$F,5,0) | G73: =VLOOKUP($A73,Fixture!$A:$F,6,0)
A74: 73 | F74: =VLOOKUP($A74,Fixture!$A:$F,5,0) | G74: =VLOOKUP($A74,Fixture!$A:$F,6,0)
A75: 74 | F75: =VLOOKUP($A75,Fixture!$A:$F,5,0) | G75: =VLOOKUP($A75,Fixture!$A:$F,6,0)
A76: 75 | F76: =VLOOKUP($A76,Fixture!$A:$F,5,0) | G76: =VLOOKUP($A76,Fixture!$A:$F,6,0)
A77: 76 | F77: =VLOOKUP($A77,Fixture!$A:$F,5,0) | G77: =VLOOKUP($A77,Fixture!$A:$F,6,0)
A78: 77 | F78: =VLOOKUP($A78,Fixture!$A:$F,5,0) | G78: =VLOOKUP($A78,Fixture!$A:$F,6,0)
A79: 78 | F79: =VLOOKUP($A79,Fixture!$A:$F,5,0) | G79: =VLOOKUP($A79,Fixture!$A:$F,6,0)
A80: 79 | F80: =VLOOKUP($A80,Fixture!$A:$F,5,0) | G80: =VLOOKUP($A80,Fixture!$A:$F,6,0)
A81: 80 | F81: =VLOOKUP($A81,Fixture!$A:$F,5,0) | G81: =VLOOKUP($A81,Fixture!$A:$F,6,0)
A82: 81 | F82: =VLOOKUP($A82,Fixture!$A:$F,5,0) | G82: =VLOOKUP($A82,Fixture!$A:$F,6,0)
A83: 82 | F83: =VLOOKUP($A83,Fixture!$A:$F,5,0) | G83: =VLOOKUP($A83,Fixture!$A:$F,6,0)
A84: 83 | F84: =VLOOKUP($A84,Fixture!$A:$F,5,0) | G84: =VLOOKUP($A84,Fixture!$A:$F,6,0)
A85: 84 | F85: =VLOOKUP($A85,Fixture!$A:$F,5,0) | G85: =VLOOKUP($A85,Fixture!$A:$F,6,0)
... A105: 104 | F105: =VLOOKUP($A105,Fixture!$A:$F,5,0) | G105: =VLOOKUP($A105,Fixture!$A:$F,6,0)
A107: Única hoja de entrada manual. Goles_A/B: marcador final incl. alargue, SIN penales. Definido_Por: 90/ET/PEN. Si PEN, registrar Ganador_Penales con el nombre canónico.

Sheet Equipos
A1: Equipo | B1: Confederacion | C1: Elo_Inicial | D1: Elo_Actual | E1: PJ | F1: Att | G1: Def | H1: Lambda_Base | J1: EQUIVALENCIAS DE NOMBRES | N1: PARÁMETROS DEL MODELO
A2: España | B2: UEFA | C2: 2210.7 | D2: =INDEX(Modelo!$AE$106:$BZ$106,MATCH($A2,Modelo!$AE$1:$BZ$1,0)) | E2: =SUMPRODUCT((Modelo!$D$3:$D$106=$A2)*Modelo!$H$3:$H$106)+SUMPRODUCT((Modelo!$E$3:$E$106=$A2)*Modelo!$H$3:$H$106) | F2: 1.3 | G2: 1.174 | H2: 1.806 | J2: Canonico | K2: results.csv | L2: worldcup.json | N2: mu (goles/partido) | O2: 2.7779
A3: Argentina | B3: CONMEBOL | C3: 2188.7 | D3: =INDEX(Modelo!$AE$106:$BZ$106,MATCH($A3,Modelo!$AE$1:$BZ$1,0)) | E3: =SUMPRODUCT((Modelo!$D$3:$D$106=$A3)*Modelo!$H$3:$H$106)+SUMPRODUCT((Modelo!$E$3:$E$106=$A3)*Modelo!$H$3:$H$106) | F3: 0.75 | G3: 0.75 | H3: 1.042 | J3: España | K3: Spain | L3: Spain | N3: beta (goles por punto Elo) | O3: 0.005078
A4: Francia | B4: UEFA | C4: 2121.7 | D4: =INDEX(Modelo!$AE$106:$BZ$106,MATCH($A4,Modelo!$AE$1:$BZ$1,0)) | E4: =SUMPRODUCT((Modelo!$D$3:$D$106=$A4)*Modelo!$H$3:$H$106)+SUMPRODUCT((Modelo!$E$3:$E$106=$A4)*Modelo!$H$3:$H$106) | F4: 1.022 | G4: 1.059 | H4: 1.42 | J4: Argentina | K4: Argentina | L4: Argentina | N4: K Mundial | O4: 60
A5: Inglaterra | B5: UEFA | C5: 2087 | D5: =INDEX(Modelo!$AE$106:$BZ$106,MATCH($A5,Modelo!$AE$1:$BZ$1,0)) | E5: =SUMPRODUCT((Modelo!$D$3:$D$106=$A5)*Modelo!$H$3:$H$106)+SUMPRODUCT((Modelo!$E$3:$E$106=$A5)*Modelo!$H$3:$H$106) | F5: 0.953 | G5: 0.815 | H5: 1.324 | J5: Francia | K5: France | L5: France | N5: Fecha de cálculo | O5: 2026-06-12
A6: Brasil | B6: CONMEBOL | C6: 2067.6 | D6: =INDEX(Modelo!$AE$106:$BZ$106,MATCH($A6,Modelo!$AE$1:$BZ$1,0)) | E6: =SUMPRODUCT((Modelo!$D$3:$D$106=$A6)*Modelo!$H$3:$H$106)+SUMPRODUCT((Modelo!$E$3:$E$106=$A6)*Modelo!$H$3:$H$106) | F6: 0.987 | G6: 1.002 | H6: 1.371 | J6: Inglaterra | K6: England | L6: England | N6: Ventana calibración | O6: 2018-01-01 a 2026-06-10
A7: Colombia | B7: CONMEBOL | C7: 2062.8 | D7: =INDEX(Modelo!$AE$106:$BZ$106,MATCH($A7,Modelo!$AE$1:$BZ$1,0)) | E7: =SUMPRODUCT((Modelo!$D$3:$D$106=$A7)*Modelo!$H$3:$H$106)+SUMPRODUCT((Modelo!$E$3:$E$106=$A7)*Modelo!$H$3:$H$106) | F7: 1.023 | G7: 0.91 | H7: 1.42 | J7: Brasil | K7: Brazil | L7: Brazil
A8: Portugal | B8: UEFA | C8: 2031.3 | D8: =INDEX(Modelo!$AE$106:$BZ$106,MATCH($A8,Modelo!$AE$1:$BZ$1,0)) | E8: =SUMPRODUCT((Modelo!$D$3:$D$106=$A8)*Modelo!$H$3:$H$106)+SUMPRODUCT((Modelo!$E$3:$E$106=$A8)*Modelo!$H$3:$H$106) | F8: 1.007 | G8: 1.076 | H8: 1.399 | J8: Colombia | K8: Colombia | L8: Colombia | N8: Elo_Inicial, Att, Def y Lambda_Base calculados el 2026-06-12 por modelo/elo_historico.py y modelo/calibrar.py (results.csv 1872→2026-06-10). Única excepción a la regla de no pegar valores (§4). Fuente Elo: calculado propio (decisión del usuario 2026-06-12; xlsx aportado quedó de respaldo en Data/).
A9: Ecuador | B9: CONMEBOL | C9: 2026.3 | D9: =INDEX(Modelo!$AE$106:$BZ$106,MATCH($A9,Modelo!$AE$1:$BZ$1,0)) | E9: =SUMPRODUCT((Modelo!$D$3:$D$106=$A9)*Modelo!$H$3:$H$106)+SUMPRODUCT((Modelo!$E$3:$E$106=$A9)*Modelo!$H$3:$H$106) | F9: 0.75 | G9: 0.75 | H9: 1.042 | J9: Portugal | K9: Portugal | L9: Portugal
A10: Países Bajos | B10: UEFA | C10: 2012.3 | D10: =INDEX(Modelo!$AE$106:$BZ$106,MATCH($A10,Modelo!$AE$1:$BZ$1,0)) | E10: =SUMPRODUCT((Modelo!$D$3:$D$106=$A10)*Modelo!$H$3:$H$106)+SUMPRODUCT((Modelo!$E$3:$E$106=$A10)*Modelo!$H$3:$H$106) | F10: 0.983 | G10: 1.148 | H10: 1.366 | J10: Ecuador | K10: Ecuador | L10: Ecuador
A11: Alemania | B11: UEFA | C11: 2007.2 | D11: =INDEX(Modelo!$AE$106:$BZ$106,MATCH($A11,Modelo!$AE$1:$BZ$1,0)) | E11: =SUMPRODUCT((Modelo!$D$3:$D$106=$A11)*Modelo!$H$3:$H$106)+SUMPRODUCT((Modelo!$E$3:$E$106=$A11)*Modelo!$H$3:$H$106) | F11: 1.173 | G11: 1.177 | H11: 1.63 | J11: Países Bajos | K11: Netherlands | L11: Netherlands
A12: Japón | B12: AFC | C12: 1992.7 | D12: =INDEX(Modelo!$AE$106:$BZ$106,MATCH($A12,Modelo!$AE$1:$BZ$1,0)) | E12: =SUMPRODUCT((Modelo!$D$3:$D$106=$A12)*Modelo!$H$3:$H$106)+SUMPRODUCT((Modelo!$E$3:$E$106=$A12)*Modelo!$H$3:$H$106) | F12: 1.093 | G12: 0.774 | H12: 1.518 | J12: Alemania | K12: Germany | L12: Germany
A13: Marruecos | B13: CAF | C13: 1984.2 | D13: =INDEX(Modelo!$AE$106:$BZ$106,MATCH($A13,Modelo!$AE$1:$BZ$1,0)) | E13: =SUMPRODUCT((Modelo!$D$3:$D$106=$A13)*Modelo!$H$3:$H$106)+SUMPRODUCT((Modelo!$E$3:$E$106=$A13)*Modelo!$H$3:$H$106) | F13: 0.886 | G13: 0.75 | H13: 1.231 | J13: Japón | K13: Japan | L13: Japan
A14: México | B14: CONCACAF | C14: 1976 | D14: =INDEX(Modelo!$AE$106:$BZ$106,MATCH($A14,Modelo!$AE$1:$BZ$1,0)) | E14: =SUMPRODUCT((Modelo!$D$3:$D$106=$A14)*Modelo!$H$3:$H$106)+SUMPRODUCT((Modelo!$E$3:$E$106=$A14)*Modelo!$H$3:$H$106) | F14: 0.861 | G14: 0.75 | H14: 1.196 | J14: Marruecos | K14: Morocco | L14: Morocco
A15: Uruguay | B15: CONMEBOL | C15: 1974.1 | D15: =INDEX(Modelo!$AE$106:$BZ$106,MATCH($A15,Modelo!$AE$1:$BZ$1,0)) | E15: =SUMPRODUCT((Modelo!$D$3:$D$106=$A15)*Modelo!$H$3:$H$106)+SUMPRODUCT((Modelo!$E$3:$E$106=$A15)*Modelo!$H$3:$H$106) | F15: 0.75 | G15: 0.75 | H15: 1.042 | J15: México | K15: Mexico | L15: Mexico
A16: Bélgica | B16: UEFA | C16: 1971.5 | D16: =INDEX(Modelo!$AE$106:$BZ$106,MATCH($A16,Modelo!$AE$1:$BZ$1,0)) | E16: =SUMPRODUCT((Modelo!$D$3:$D$106=$A16)*Modelo!$H$3:$H$106)+SUMPRODUCT((Modelo!$E$3:$E$106=$A16)*Modelo!$H$3:$H$106) | F16: 1.009 | G16: 1.108 | H16: 1.402 | J16: Uruguay | K16: Uruguay | L16: Uruguay
A17: Croacia | B17: UEFA | C17: 1964.1 | D17: =INDEX(Modelo!$AE$106:$BZ$106,MATCH($A17,Modelo!$AE$1:$BZ$1,0)) | E17: =SUMPRODUCT((Modelo!$D$3:$D$106=$A17)*Modelo!$H$3:$H$106)+SUMPRODUCT((Modelo!$E$3:$E$106=$A17)*Modelo!$H$3:$H$106) | F17: 0.917 | G17: 1.082 | H17: 1.274 | J17: Bélgica | K17: Belgium | L17: Belgium
A18: Turquía | B18: UEFA | C18: 1962.9 | D18: =INDEX(Modelo!$AE$106:$BZ$106,MATCH($A18,Modelo!$AE$1:$BZ$1,0)) | E18: =SUMPRODUCT((Modelo!$D$3:$D$106=$A18)*Modelo!$H$3:$H$106)+SUMPRODUCT((Modelo!$E$3:$E$106=$A18)*Modelo!$H$3:$H$106) | F18: 1.254 | G18: 1.06 | H18: 1.742 | J18: Croacia | K18: Croatia | L18: Croatia
A19: Suiza | B19: UEFA | C19: 1960.6 | D19: =INDEX(Modelo!$AE$106:$BZ$106,MATCH($A19,Modelo!$AE$1:$BZ$1,0)) | E19: =SUMPRODUCT((Modelo!$D$3:$D$106=$A19)*Modelo!$H$3:$H$106)+SUMPRODUCT((Modelo!$E$3:$E$106=$A19)*Modelo!$H$3:$H$106) | F19: 1.074 | G19: 0.954 | H19: 1.492 | J19: Turquía | K19: Turkey | L19: Turkey
A20: Noruega | B20: UEFA | C20: 1956.7 | D20: =INDEX(Modelo!$AE$106:$BZ$106,MATCH($A20,Modelo!$AE$1:$BZ$1,0)) | E20: =SUMPRODUCT((Modelo!$D$3:$D$106=$A20)*Modelo!$H$3:$H$106)+SUMPRODUCT((Modelo!$E$3:$E$106=$A20)*Modelo!$H$3:$H$106) | F20: 1.3 | G20: 0.821 | H20: 1.806 | J20: Suiza | K20: Switzerland | L20: Switzerland
... A49: Qatar | B49: AFC | C49: 1566 | D49: =INDEX(Modelo!$AE$106:$BZ$106,MATCH($A49,Modelo!$AE$1:$BZ$1,0)) | E49: =SUMPRODUCT((Modelo!$D$3:$D$106=$A49)*Modelo!$H$3:$H$106)+SUMPRODUCT((Modelo!$E$3:$E$106=$A49)*Modelo!$H$3:$H$106) | F49: 0.825 | G49: 1.207 | H49: 1.146 | J49: Curaçao | K49: Curaçao | L49: Curaçao
J50: Qatar | K50: Qatar | L50: Qatar

Sheet Modelo
A1: ID | B1: Fecha | C1: Fase | D1: Equipo_A | E1: Equipo_B | F1: Loc_A | G1: Loc_B | H1: Jugado | I1: GA | J1: GB | K1: Elo_A_pre | L1: Elo_B_pre | M1: dr | N1: E_A | O1: S_A | P1: G_mult | Q1: Delta_A | R1: Elo_A_post | S1: Elo_B_post | T1: Δ_goles | U1: Att_A | V1: Def_A | W1: Att_B | X1: Def_B | Y1: Total | Z1: λ_A | AA1: λ_B | AE1: =Equipos!$A2 | AF1: =Equipos!$A3 | AG1: =Equipos!$A4 | AH1: =Equipos!$A5 | AI1: =Equipos!$A6 | AJ1: =Equipos!$A7 | AK1: =Equipos!$A8 | AL1: =Equipos!$A9 | AM1: =Equipos!$A10 | AN1: =Equipos!$A11 | AO1: =Equipos!$A12 | AP1: =Equipos!$A13 | AQ1: =Equipos!$A14 | AR1: =Equipos!$A15 | AS1: =Equipos!$A16 | AT1: =Equipos!$A17 | AU1: =Equipos!$A18 | AV1: =Equipos!$A19 | AW1: =Equipos!$A20 | AX1: =Equipos!$A21 | AY1: =Equipos!$A22 | AZ1: =Equipos!$A23 | BA1: =Equipos!$A24 | BB1: =Equipos!$A25 | BC1: =Equipos!$A26 | BD1: =Equipos!$A27 | BE1: =Equipos!$A28 | BF1: =Equipos!$A29 | BG1: =Equipos!$A30 | BH1: =Equipos!$A31 | BI1: =Equipos!$A32 | BJ1: =Equipos!$A33 | BK1: =Equipos!$A34 | BL1: =Equipos!$A35 | BM1: =Equipos!$A36 | BN1: =Equipos!$A37 | BO1: =Equipos!$A38 | BP1: =Equipos!$A39 | BQ1: =Equipos!$A40 | BR1: =Equipos!$A41 | BS1: =Equipos!$A42 | BT1: =Equipos!$A43 | BU1: =Equipos!$A44 | BV1: =Equipos!$A45 | BW1: =Equipos!$A46 | BX1: =Equipos!$A47 | BY1: =Equipos!$A48 | BZ1: =Equipos!$A49
A2: INICIAL | AE2: =VLOOKUP(AE$1,Equipos!$A:$C,3,0) | AF2: =VLOOKUP(AF$1,Equipos!$A:$C,3,0) | AG2: =VLOOKUP(AG$1,Equipos!$A:$C,3,0) | AH2: =VLOOKUP(AH$1,Equipos!$A:$C,3,0) | AI2: =VLOOKUP(AI$1,Equipos!$A:$C,3,0) | AJ2: =VLOOKUP(AJ$1,Equipos!$A:$C,3,0) | AK2: =VLOOKUP(AK$1,Equipos!$A:$C,3,0) | AL2: =VLOOKUP(AL$1,Equipos!$A:$C,3,0) | ... BZ2: =VLOOKUP(BZ$1,Equipos!$A:$C,3,0)
A3: =Fixture!A2 | B3: =Fixture!B2 | C3: =Fixture!C2 | D3: =Fixture!E2 | E3: =Fixture!F2 | F3: =Fixture!J2 | G3: =Fixture!K2 | H3: =IF(ISNUMBER(Resultados!B2),1,0) | I3: =IF($H3=1,Resultados!B2,0) | J3: =IF($H3=1,Resultados!C2,0) | K3: =IFERROR(INDEX($AE2:$BZ2,MATCH($D3,$AE$1:$BZ$1,0)),"") | L3: =IFERROR(INDEX($AE2:$BZ2,MATCH($E3,$AE$1:$BZ$1,0)),"") | M3: =IF(OR($K3="",$L3=""),"",($K3+100*$F3)-($L3+100*$G3)) | N3: =IF($M3="","",1/(1+10^(-$M3/400))) | O3: =IF(OR($H3=0,$N3=""),"",IF($I3>$J3,1,IF($I3=$J3,0.5,0))) | P3: =IF($O3="","",IF(ABS($I3-$J3)<=1,1,IF(ABS($I3-$J3)=2,1.5,IF(ABS($I3-$J3)=3,1.75,1.75+(ABS($I3-$J3)-3)/8)))) | Q3: =IF($O3="",0,Equipos!$O$4*$P3*($O3-$N3)) | R3: =IF($K3="","",$K3+$Q3) | S3: =IF($L3="","",$L3-$Q3) | T3: =IF($M3="","",Equipos!$O$3*$M3) | U3: =IFERROR(VLOOKUP($D3,Equipos!$A:$H,6,0),"") | V3: =IFERROR(VLOOKUP($D3,Equipos!$A:$H,7,0),"") | W3: =IFERROR(VLOOKUP($E3,Equipos!$A:$H,6,0),"") | X3: =IFERROR(VLOOKUP($E3,Equipos!$A:$H,7,0),"") | Y3: =IF(OR($U3="",$W3=""),"",MIN(3.6,MAX(1.8,Equipos!$O$2*SQRT($U3*$W3*$V3*$X3)))) | Z3: =IF(OR($Y3="",$T3=""),"",MAX(0.2,($Y3+$T3)/2)) | AA3: =IF(OR($Y3="",$T3=""),"",MAX(0.2,($Y3-$T3)/2)) | AE3: =IF($D3=AE$1,$R3,IF($E3=AE$1,$S3,AE2)) | AF3: =IF($D3=AF$1,$R3,IF($E3=AF$1,$S3,AF2)) | AG3: =IF($D3=AG$1,$R3,IF($E3=AG$1,$S3,AG2)) | AH3: =IF($D3=AH$1,$R3,IF($E3=AH$1,$S3,AH2)) | AI3: =IF($D3=AI$1,$R3,IF($E3=AI$1,$S3,AI2)) | AJ3: =IF($D3=AJ$1,$R3,IF($E3=AJ$1,$S3,AJ2)) | AK3: =IF($D3=AK$1,$R3,IF($E3=AK$1,$S3,AK2)) | AL3: =IF($D3=AL$1,$R3,IF($E3=AL$1,$S3,AL2)) | ... BZ3: =IF($D3=BZ$1,$R3,IF($E3=BZ$1,$S3,BZ2))
A4: =Fixture!A3 | B4: =Fixture!B3 | C4: =Fixture!C3 | D4: =Fixture!E3 | E4: =Fixture!F3 | F4: =Fixture!J3 | G4: =Fixture!K3 | H4: =IF(ISNUMBER(Resultados!B3),1,0) | I4: =IF($H4=1,Resultados!B3,0) | J4: =IF($H4=1,Resultados!C3,0) | K4: =IFERROR(INDEX($AE3:$BZ3,MATCH($D4,$AE$1:$BZ$1,0)),"") | L4: =IFERROR(INDEX($AE3:$BZ3,MATCH($E4,$AE$1:$BZ$1,0)),"") | M4: =IF(OR($K4="",$L4=""),"",($K4+100*$F4)-($L4+100*$G4)) | N4: =IF($M4="","",1/(1+10^(-$M4/400))) | O4: =IF(OR($H4=0,$N4=""),"",IF($I4>$J4,1,IF($I4=$J4,0.5,0))) | P4: =IF($O4="","",IF(ABS($I4-$J4)<=1,1,IF(ABS($I4-$J4)=2,1.5,IF(ABS($I4-$J4)=3,1.75,1.75+(ABS($I4-$J4)-3)/8)))) | Q4: =IF($O4="",0,Equipos!$O$4*$P4*($O4-$N4)) | R4: =IF($K4="","",$K4+$Q4) | S4: =IF($L4="","",$L4-$Q4) | T4: =IF($M4="","",Equipos!$O$3*$M4) | U4: =IFERROR(VLOOKUP($D4,Equipos!$A:$H,6,0),"") | V4: =IFERROR(VLOOKUP($D4,Equipos!$A:$H,7,0),"") | W4: =IFERROR(VLOOKUP($E4,Equipos!$A:$H,6,0),"") | X4: =IFERROR(VLOOKUP($E4,Equipos!$A:$H,7,0),"") | Y4: =IF(OR($U4="",$W4=""),"",MIN(3.6,MAX(1.8,Equipos!$O$2*SQRT($U4*$W4*$V4*$X4)))) | Z4: =IF(OR($Y4="",$T4=""),"",MAX(0.2,($Y4+$T4)/2)) | AA4: =IF(OR($Y4="",$T4=""),"",MAX(0.2,($Y4-$T4)/2)) | AE4: =IF($D4=AE$1,$R4,IF($E4=AE$1,$S4,AE3)) | AF4: =IF($D4=AF$1,$R4,IF($E4=AF$1,$S4,AF3)) | AG4: =IF($D4=AG$1,$R4,IF($E4=AG$1,$S4,AG3)) | AH4: =IF($D4=AH$1,$R4,IF($E4=AH$1,$S4,AH3)) | AI4: =IF($D4=AI$1,$R4,IF($E4=AI$1,$S4,AI3)) | AJ4: =IF($D4=AJ$1,$R4,IF($E4=AJ$1,$S4,AJ3)) | AK4: =IF($D4=AK$1,$R4,IF($E4=AK$1,$S4,AK3)) | AL4: =IF($D4=AL$1,$R4,IF($E4=AL$1,$S4,AL3)) | ... BZ4: =IF($D4=BZ$1,$R4,IF($E4=BZ$1,$S4,BZ3))
A5: =Fixture!A4 | B5: =Fixture!B4 | C5: =Fixture!C4 | D5: =Fixture!E4 | E5: =Fixture!F4 | F5: =Fixture!J4 | G5: =Fixture!K4 | H5: =IF(ISNUMBER(Resultados!B4),1,0) | I5: =IF($H5=1,Resultados!B4,0) | J5: =IF($H5=1,Resultados!C4,0) | K5: =IFERROR(INDEX($AE4:$BZ4,MATCH($D5,$AE$1:$BZ$1,0)),"") | L5: =IFERROR(INDEX($AE4:$BZ4,MATCH($E5,$AE$1:$BZ$1,0)),"") | M5: =IF(OR($K5="",$L5=""),"",($K5+100*$F5)-($L5+100*$G5)) | N5: =IF($M5="","",1/(1+10^(-$M5/400))) | O5: =IF(OR($H5=0,$N5=""),"",IF($I5>$J5,1,IF($I5=$J5,0.5,0))) | P5: =IF($O5="","",IF(ABS($I5-$J5)<=1,1,IF(ABS($I5-$J5)=2,1.5,IF(ABS($I5-$J5)=3,1.75,1.75+(ABS($I5-$J5)-3)/8)))) | Q5: =IF($O5="",0,Equipos!$O$4*$P5*($O5-$N5)) | R5: =IF($K5="","",$K5+$Q5) | S5: =IF($L5="","",$L5-$Q5) | T5: =IF($M5="","",Equipos!$O$3*$M5) | U5: =IFERROR(VLOOKUP($D5,Equipos!$A:$H,6,0),"") | V5: =IFERROR(VLOOKUP($D5,Equipos!$A:$H,7,0),"") | W5: =IFERROR(VLOOKUP($E5,Equipos!$A:$H,6,0),"") | X5: =IFERROR(VLOOKUP($E5,Equipos!$A:$H,7,0),"") | Y5: =IF(OR($U5="",$W5=""),"",MIN(3.6,MAX(1.8,Equipos!$O$2*SQRT($U5*$W5*$V5*$X5)))) | Z5: =IF(OR($Y5="",$T5=""),"",MAX(0.2,($Y5+$T5)/2)) | AA5: =IF(OR($Y5="",$T5=""),"",MAX(0.2,($Y5-$T5)/2)) | AE5: =IF($D5=AE$1,$R5,IF($E5=AE$1,$S5,AE4)) | AF5: =IF($D5=AF$1,$R5,IF($E5=AF$1,$S5,AF4)) | AG5: =IF($D5=AG$1,$R5,IF($E5=AG$1,$S5,AG4)) | AH5: =IF($D5=AH$1,$R5,IF($E5=AH$1,$S5,AH4)) | AI5: =IF($D5=AI$1,$R5,IF($E5=AI$1,$S5,AI4)) | AJ5: =IF($D5=AJ$1,$R5,IF($E5=AJ$1,$S5,AJ4)) | AK5: =IF($D5=AK$1,$R5,IF($E5=AK$1,$S5,AK4)) | AL5: =IF($D5=AL$1,$R5,IF($E5=AL$1,$S5,AL4)) | ... BZ5: =IF($D5=BZ$1,$R5,IF($E5=BZ$1,$S5,BZ4))
A6: =Fixture!A5 | B6: =Fixture!B5 | C6: =Fixture!C5 | D6: =Fixture!E5 | E6: =Fixture!F5 | F6: =Fixture!J5 | G6: =Fixture!K5 | H6: =IF(ISNUMBER(Resultados!B5),1,0) | I6: =IF($H6=1,Resultados!B5,0) | J6: =IF($H6=1,Resultados!C5,0) | K6: =IFERROR(INDEX($AE5:$BZ5,MATCH($D6,$AE$1:$BZ$1,0)),"") | L6: =IFERROR(INDEX($AE5:$BZ5,MATCH($E6,$AE$1:$BZ$1,0)),"") | M6: =IF(OR($K6="",$L6=""),"",($K6+100*$F6)-($L6+100*$G6)) | N6: =IF($M6="","",1/(1+10^(-$M6/400))) | O6: =IF(OR($H6=0,$N6=""),"",IF($I6>$J6,1,IF($I6=$J6,0.5,0))) | P6: =IF($O6="","",IF(ABS($I6-$J6)<=1,1,IF(ABS($I6-$J6)=2,1.5,IF(ABS($I6-$J6)=3,1.75,1.75+(ABS($I6-$J6)-3)/8)))) | Q6: =IF($O6="",0,Equipos!$O$4*$P6*($O6-$N6)) | R6: =IF($K6="","",$K6+$Q6) | S6: =IF($L6="","",$L6-$Q6) | T6: =IF($M6="","",Equipos!$O$3*$M6) | U6: =IFERROR(VLOOKUP($D6,Equipos!$A:$H,6,0),"") | V6: =IFERROR(VLOOKUP($D6,Equipos!$A:$H,7,0),"") | W6: =IFERROR(VLOOKUP($E6,Equipos!$A:$H,6,0),"") | X6: =IFERROR(VLOOKUP($E6,Equipos!$A:$H,7,0),"") | Y6: =IF(OR($U6="",$W6=""),"",MIN(3.6,MAX(1.8,Equipos!$O$2*SQRT($U6*$W6*$V6*$X6)))) | Z6: =IF(OR($Y6="",$T6=""),"",MAX(0.2,($Y6+$T6)/2)) | AA6: =IF(OR($Y6="",$T6=""),"",MAX(0.2,($Y6-$T6)/2)) | AE6: =IF($D6=AE$1,$R6,IF($E6=AE$1,$S6,AE5)) | AF6: =IF($D6=AF$1,$R6,IF($E6=AF$1,$S6,AF5)) | AG6: =IF($D6=AG$1,$R6,IF($E6=AG$1,$S6,AG5)) | AH6: =IF($D6=AH$1,$R6,IF($E6=AH$1,$S6,AH5)) | AI6: =IF($D6=AI$1,$R6,IF($E6=AI$1,$S6,AI5)) | AJ6: =IF($D6=AJ$1,$R6,IF($E6=AJ$1,$S6,AJ5)) | AK6: =IF($D6=AK$1,$R6,IF($E6=AK$1,$S6,AK5)) | AL6: =IF($D6=AL$1,$R6,IF($E6=AL$1,$S6,AL5)) | ... BZ6: =IF($D6=BZ$1,$R6,IF($E6=BZ$1,$S6,BZ5))
A7: =Fixture!A6 | B7: =Fixture!B6 | C7: =Fixture!C6 | D7: =Fixture!E6 | E7: =Fixture!F6 | F7: =Fixture!J6 | G7: =Fixture!K6 | H7: =IF(ISNUMBER(Resultados!B6),1,0) | I7: =IF($H7=1,Resultados!B6,0) | J7: =IF($H7=1,Resultados!C6,0) | K7: =IFERROR(INDEX($AE6:$BZ6,MATCH($D7,$AE$1:$BZ$1,0)),"") | L7: =IFERROR(INDEX($AE6:$BZ6,MATCH($E7,$AE$1:$BZ$1,0)),"") | M7: =IF(OR($K7="",$L7=""),"",($K7+100*$F7)-($L7+100*$G7)) | N7: =IF($M7="","",1/(1+10^(-$M7/400))) | O7: =IF(OR($H7=0,$N7=""),"",IF($I7>$J7,1,IF($I7=$J7,0.5,0))) | P7: =IF($O7="","",IF(ABS($I7-$J7)<=1,1,IF(ABS($I7-$J7)=2,1.5,IF(ABS($I7-$J7)=3,1.75,1.75+(ABS($I7-$J7)-3)/8)))) | Q7: =IF($O7="",0,Equipos!$O$4*$P7*($O7-$N7)) | R7: =IF($K7="","",$K7+$Q7) | S7: =IF($L7="","",$L7-$Q7) | T7: =IF($M7="","",Equipos!$O$3*$M7) | U7: =IFERROR(VLOOKUP($D7,Equipos!$A:$H,6,0),"") | V7: =IFERROR(VLOOKUP($D7,Equipos!$A:$H,7,0),"") | W7: =IFERROR(VLOOKUP($E7,Equipos!$A:$H,6,0),"") | X7: =IFERROR(VLOOKUP($E7,Equipos!$A:$H,7,0),"") | Y7: =IF(OR($U7="",$W7=""),"",MIN(3.6,MAX(1.8,Equipos!$O$2*SQRT($U7*$W7*$V7*$X7)))) | Z7: =IF(OR($Y7="",$T7=""),"",MAX(0.2,($Y7+$T7)/2)) | AA7: =IF(OR($Y7="",$T7=""),"",MAX(0.2,($Y7-$T7)/2)) | AE7: =IF($D7=AE$1,$R7,IF($E7=AE$1,$S7,AE6)) | AF7: =IF($D7=AF$1,$R7,IF($E7=AF$1,$S7,AF6)) | AG7: =IF($D7=AG$1,$R7,IF($E7=AG$1,$S7,AG6)) | AH7: =IF($D7=AH$1,$R7,IF($E7=AH$1,$S7,AH6)) | AI7: =IF($D7=AI$1,$R7,IF($E7=AI$1,$S7,AI6)) | AJ7: =IF($D7=AJ$1,$R7,IF($E7=AJ$1,$S7,AJ6)) | AK7: =IF($D7=AK$1,$R7,IF($E7=AK$1,$S7,AK6)) | AL7: =IF($D7=AL$1,$R7,IF($E7=AL$1,$S7,AL6)) | ... BZ7: =IF($D7=BZ$1,$R7,IF($E7=BZ$1,$S7,BZ6))
A8: =Fixture!A7 | B8: =Fixture!B7 | C8: =Fixture!C7 | D8: =Fixture!E7 | E8: =Fixture!F7 | F8: =Fixture!J7 | G8: =Fixture!K7 | H8: =IF(ISNUMBER(Resultados!B7),1,0) | I8: =IF($H8=1,Resultados!B7,0) | J8: =IF($H8=1,Resultados!C7,0) | K8: =IFERROR(INDEX($AE7:$BZ7,MATCH($D8,$AE$1:$BZ$1,0)),"") | L8: =IFERROR(INDEX($AE7:$BZ7,MATCH($E8,$AE$1:$BZ$1,0)),"") | M8: =IF(OR($K8="",$L8=""),"",($K8+100*$F8)-($L8+100*$G8)) | N8: =IF($M8="","",1/(1+10^(-$M8/400))) | O8: =IF(OR($H8=0,$N8=""),"",IF($I8>$J8,1,IF($I8=$J8,0.5,0))) | P8: =IF($O8="","",IF(ABS($I8-$J8)<=1,1,IF(ABS($I8-$J8)=2,1.5,IF(ABS($I8-$J8)=3,1.75,1.75+(ABS($I8-$J8)-3)/8)))) | Q8: =IF($O8="",0,Equipos!$O$4*$P8*($O8-$N8)) | R8: =IF($K8="","",$K8+$Q8) | S8: =IF($L8="","",$L8-$Q8) | T8: =IF($M8="","",Equipos!$O$3*$M8) | U8: =IFERROR(VLOOKUP($D8,Equipos!$A:$H,6,0),"") | V8: =IFERROR(VLOOKUP($D8,Equipos!$A:$H,7,0),"") | W8: =IFERROR(VLOOKUP($E8,Equipos!$A:$H,6,0),"") | X8: =IFERROR(VLOOKUP($E8,Equipos!$A:$H,7,0),"") | Y8: =IF(OR($U8="",$W8=""),"",MIN(3.6,MAX(1.8,Equipos!$O$2*SQRT($U8*$W8*$V8*$X8)))) | Z8: =IF(OR($Y8="",$T8=""),"",MAX(0.2,($Y8+$T8)/2)) | AA8: =IF(OR($Y8="",$T8=""),"",MAX(0.2,($Y8-$T8)/2)) | AE8: =IF($D8=AE$1,$R8,IF($E8=AE$1,$S8,AE7)) | AF8: =IF($D8=AF$1,$R8,IF($E8=AF$1,$S8,AF7)) | AG8: =IF($D8=AG$1,$R8,IF($E8=AG$1,$S8,AG7)) | AH8: =IF($D8=AH$1,$R8,IF($E8=AH$1,$S8,AH7)) | AI8: =IF($D8=AI$1,$R8,IF($E8=AI$1,$S8,AI7)) | AJ8: =IF($D8=AJ$1,$R8,IF($E8=AJ$1,$S8,AJ7)) | AK8: =IF($D8=AK$1,$R8,IF($E8=AK$1,$S8,AK7)) | AL8: =IF($D8=AL$1,$R8,IF($E8=AL$1,$S8,AL7)) | ... BZ8: =IF($D8=BZ$1,$R8,IF($E8=BZ$1,$S8,BZ7))
A9: =Fixture!A8 | B9: =Fixture!B8 | C9: =Fixture!C8 | D9: =Fixture!E8 | E9: =Fixture!F8 | F9: =Fixture!J8 | G9: =Fixture!K8 | H9: =IF(ISNUMBER(Resultados!B8),1,0) | I9: =IF($H9=1,Resultados!B8,0) | J9: =IF($H9=1,Resultados!C8,0) | K9: =IFERROR(INDEX($AE8:$BZ8,MATCH($D9,$AE$1:$BZ$1,0)),"") | L9: =IFERROR(INDEX($AE8:$BZ8,MATCH($E9,$AE$1:$BZ$1,0)),"") | M9: =IF(OR($K9="",$L9=""),"",($K9+100*$F9)-($L9+100*$G9)) | N9: =IF($M9="","",1/(1+10^(-$M9/400))) | O9: =IF(OR($H9=0,$N9=""),"",IF($I9>$J9,1,IF($I9=$J9,0.5,0))) | P9: =IF($O9="","",IF(ABS($I9-$J9)<=1,1,IF(ABS($I9-$J9)=2,1.5,IF(ABS($I9-$J9)=3,1.75,1.75+(ABS($I9-$J9)-3)/8)))) | Q9: =IF($O9="",0,Equipos!$O$4*$P9*($O9-$N9)) | R9: =IF($K9="","",$K9+$Q9) | S9: =IF($L9="","",$L9-$Q9) | T9: =IF($M9="","",Equipos!$O$3*$M9) | U9: =IFERROR(VLOOKUP($D9,Equipos!$A:$H,6,0),"") | V9: =IFERROR(VLOOKUP($D9,Equipos!$A:$H,7,0),"") | W9: =IFERROR(VLOOKUP($E9,Equipos!$A:$H,6,0),"") | X9: =IFERROR(VLOOKUP($E9,Equipos!$A:$H,7,0),"") | Y9: =IF(OR($U9="",$W9=""),"",MIN(3.6,MAX(1.8,Equipos!$O$2*SQRT($U9*$W9*$V9*$X9)))) | Z9: =IF(OR($Y9="",$T9=""),"",MAX(0.2,($Y9+$T9)/2)) | AA9: =IF(OR($Y9="",$T9=""),"",MAX(0.2,($Y9-$T9)/2)) | AE9: =IF($D9=AE$1,$R9,IF($E9=AE$1,$S9,AE8)) | AF9: =IF($D9=AF$1,$R9,IF($E9=AF$1,$S9,AF8)) | AG9: =IF($D9=AG$1,$R9,IF($E9=AG$1,$S9,AG8)) | AH9: =IF($D9=AH$1,$R9,IF($E9=AH$1,$S9,AH8)) | AI9: =IF($D9=AI$1,$R9,IF($E9=AI$1,$S9,AI8)) | AJ9: =IF($D9=AJ$1,$R9,IF($E9=AJ$1,$S9,AJ8)) | AK9: =IF($D9=AK$1,$R9,IF($E9=AK$1,$S9,AK8)) | AL9: =IF($D9=AL$1,$R9,IF($E9=AL$1,$S9,AL8)) | ... BZ9: =IF($D9=BZ$1,$R9,IF($E9=BZ$1,$S9,BZ8))
A10: =Fixture!A9 | B10: =Fixture!B9 | C10: =Fixture!C9 | D10: =Fixture!E9 | E10: =Fixture!F9 | F10: =Fixture!J9 | G10: =Fixture!K9 | H10: =IF(ISNUMBER(Resultados!B9),1,0) | I10: =IF($H10=1,Resultados!B9,0) | J10: =IF($H10=1,Resultados!C9,0) | K10: =IFERROR(INDEX($AE9:$BZ9,MATCH($D10,$AE$1:$BZ$1,0)),"") | L10: =IFERROR(INDEX($AE9:$BZ9,MATCH($E10,$AE$1:$BZ$1,0)),"") | M10: =IF(OR($K10="",$L10=""),"",($K10+100*$F10)-($L10+100*$G10)) | N10: =IF($M10="","",1/(1+10^(-$M10/400))) | O10: =IF(OR($H10=0,$N10=""),"",IF($I10>$J10,1,IF($I10=$J10,0.5,0))) | P10: =IF($O10="","",IF(ABS($I10-$J10)<=1,1,IF(ABS($I10-$J10)=2,1.5,IF(ABS($I10-$J10)=3,1.75,1.75+(ABS($I10-$J10)-3)/8)))) | Q10: =IF($O10="",0,Equipos!$O$4*$P10*($O10-$N10)) | R10: =IF($K10="","",$K10+$Q10) | S10: =IF($L10="","",$L10-$Q10) | T10: =IF($M10="","",Equipos!$O$3*$M10) | U10: =IFERROR(VLOOKUP($D10,Equipos!$A:$H,6,0),"") | V10: =IFERROR(VLOOKUP($D10,Equipos!$A:$H,7,0),"") | W10: =IFERROR(VLOOKUP($E10,Equipos!$A:$H,6,0),"") | X10: =IFERROR(VLOOKUP($E10,Equipos!$A:$H,7,0),"") | Y10: =IF(OR($U10="",$W10=""),"",MIN(3.6,MAX(1.8,Equipos!$O$2*SQRT($U10*$W10*$V10*$X10)))) | Z10: =IF(OR($Y10="",$T10=""),"",MAX(0.2,($Y10+$T10)/2)) | AA10: =IF(OR($Y10="",$T10=""),"",MAX(0.2,($Y10-$T10)/2)) | AE10: =IF($D10=AE$1,$R10,IF($E10=AE$1,$S10,AE9)) | AF10: =IF($D10=AF$1,$R10,IF($E10=AF$1,$S10,AF9)) | AG10: =IF($D10=AG$1,$R10,IF($E10=AG$1,$S10,AG9)) | AH10: =IF($D10=AH$1,$R10,IF($E10=AH$1,$S10,AH9)) | AI10: =IF($D10=AI$1,$R10,IF($E10=AI$1,$S10,AI9)) | AJ10: =IF($D10=AJ$1,$R10,IF($E10=AJ$1,$S10,AJ9)) | AK10: =IF($D10=AK$1,$R10,IF($E10=AK$1,$S10,AK9)) | AL10: =IF($D10=AL$1,$R10,IF($E10=AL$1,$S10,AL9)) | ... BZ10: =IF($D10=BZ$1,$R10,IF($E10=BZ$1,$S10,BZ9))
A11: =Fixture!A10 | B11: =Fixture!B10 | C11: =Fixture!C10 | D11: =Fixture!E10 | E11: =Fixture!F10 | F11: =Fixture!J10 | G11: =Fixture!K10 | H11: =IF(ISNUMBER(Resultados!B10),1,0) | I11: =IF($H11=1,Resultados!B10,0) | J11: =IF($H11=1,Resultados!C10,0) | K11: =IFERROR(INDEX($AE10:$BZ10,MATCH($D11,$AE$1:$BZ$1,0)),"") | L11: =IFERROR(INDEX($AE10:$BZ10,MATCH($E11,$AE$1:$BZ$1,0)),"") | M11: =IF(OR($K11="",$L11=""),"",($K11+100*$F11)-($L11+100*$G11)) | N11: =IF($M11="","",1/(1+10^(-$M11/400))) | O11: =IF(OR($H11=0,$N11=""),"",IF($I11>$J11,1,IF($I11=$J11,0.5,0))) | P11: =IF($O11="","",IF(ABS($I11-$J11)<=1,1,IF(ABS($I11-$J11)=2,1.5,IF(ABS($I11-$J11)=3,1.75,1.75+(ABS($I11-$J11)-3)/8)))) | Q11: =IF($O11="",0,Equipos!$O$4*$P11*($O11-$N11)) | R11: =IF($K11="","",$K11+$Q11) | S11: =IF($L11="","",$L11-$Q11) | T11: =IF($M11="","",Equipos!$O$3*$M11) | U11: =IFERROR(VLOOKUP($D11,Equipos!$A:$H,6,0),"") | V11: =IFERROR(VLOOKUP($D11,Equipos!$A:$H,7,0),"") | W11: =IFERROR(VLOOKUP($E11,Equipos!$A:$H,6,0),"") | X11: =IFERROR(VLOOKUP($E11,Equipos!$A:$H,7,0),"") | Y11: =IF(OR($U11="",$W11=""),"",MIN(3.6,MAX(1.8,Equipos!$O$2*SQRT($U11*$W11*$V11*$X11)))) | Z11: =IF(OR($Y11="",$T11=""),"",MAX(0.2,($Y11+$T11)/2)) | AA11: =IF(OR($Y11="",$T11=""),"",MAX(0.2,($Y11-$T11)/2)) | AE11: =IF($D11=AE$1,$R11,IF($E11=AE$1,$S11,AE10)) | AF11: =IF($D11=AF$1,$R11,IF($E11=AF$1,$S11,AF10)) | AG11: =IF($D11=AG$1,$R11,IF($E11=AG$1,$S11,AG10)) | AH11: =IF($D11=AH$1,$R11,IF($E11=AH$1,$S11,AH10)) | AI11: =IF($D11=AI$1,$R11,IF($E11=AI$1,$S11,AI10)) | AJ11: =IF($D11=AJ$1,$R11,IF($E11=AJ$1,$S11,AJ10)) | AK11: =IF($D11=AK$1,$R11,IF($E11=AK$1,$S11,AK10)) | AL11: =IF($D11=AL$1,$R11,IF($E11=AL$1,$S11,AL10)) | ... BZ11: =IF($D11=BZ$1,$R11,IF($E11=BZ$1,$S11,BZ10))
A12: =Fixture!A11 | B12: =Fixture!B11 | C12: =Fixture!C11 | D12: =Fixture!E11 | E12: =Fixture!F11 | F12: =Fixture!J11 | G12: =Fixture!K11 | H12: =IF(ISNUMBER(Resultados!B11),1,0) | I12: =IF($H12=1,Resultados!B11,0) | J12: =IF($H12=1,Resultados!C11,0) | K12: =IFERROR(INDEX($AE11:$BZ11,MATCH($D12,$AE$1:$BZ$1,0)),"") | L12: =IFERROR(INDEX($AE11:$BZ11,MATCH($E12,$AE$1:$BZ$1,0)),"") | M12: =IF(OR($K12="",$L12=""),"",($K12+100*$F12)-($L12+100*$G12)) | N12: =IF($M12="","",1/(1+10^(-$M12/400))) | O12: =IF(OR($H12=0,$N12=""),"",IF($I12>$J12,1,IF($I12=$J12,0.5,0))) | P12: =IF($O12="","",IF(ABS($I12-$J12)<=1,1,IF(ABS($I12-$J12)=2,1.5,IF(ABS($I12-$J12)=3,1.75,1.75+(ABS($I12-$J12)-3)/8)))) | Q12: =IF($O12="",0,Equipos!$O$4*$P12*($O12-$N12)) | R12: =IF($K12="","",$K12+$Q12) | S12: =IF($L12="","",$L12-$Q12) | T12: =IF($M12="","",Equipos!$O$3*$M12) | U12: =IFERROR(VLOOKUP($D12,Equipos!$A:$H,6,0),"") | V12: =IFERROR(VLOOKUP($D12,Equipos!$A:$H,7,0),"") | W12: =IFERROR(VLOOKUP($E12,Equipos!$A:$H,6,0),"") | X12: =IFERROR(VLOOKUP($E12,Equipos!$A:$H,7,0),"") | Y12: =IF(OR($U12="",$W12=""),"",MIN(3.6,MAX(1.8,Equipos!$O$2*SQRT($U12*$W12*$V12*$X12)))) | Z12: =IF(OR($Y12="",$T12=""),"",MAX(0.2,($Y12+$T12)/2)) | AA12: =IF(OR($Y12="",$T12=""),"",MAX(0.2,($Y12-$T12)/2)) | AE12: =IF($D12=AE$1,$R12,IF($E12=AE$1,$S12,AE11)) | AF12: =IF($D12=AF$1,$R12,IF($E12=AF$1,$S12,AF11)) | AG12: =IF($D12=AG$1,$R12,IF($E12=AG$1,$S12,AG11)) | AH12: =IF($D12=AH$1,$R12,IF($E12=AH$1,$S12,AH11)) | AI12: =IF($D12=AI$1,$R12,IF($E12=AI$1,$S12,AI11)) | AJ12: =IF($D12=AJ$1,$R12,IF($E12=AJ$1,$S12,AJ11)) | AK12: =IF($D12=AK$1,$R12,IF($E12=AK$1,$S12,AK11)) | AL12: =IF($D12=AL$1,$R12,IF($E12=AL$1,$S12,AL11)) | ... BZ12: =IF($D12=BZ$1,$R12,IF($E12=BZ$1,$S12,BZ11))
A13: =Fixture!A12 | B13: =Fixture!B12 | C13: =Fixture!C12 | D13: =Fixture!E12 | E13: =Fixture!F12 | F13: =Fixture!J12 | G13: =Fixture!K12 | H13: =IF(ISNUMBER(Resultados!B12),1,0) | I13: =IF($H13=1,Resultados!B12,0) | J13: =IF($H13=1,Resultados!C12,0) | K13: =IFERROR(INDEX($AE12:$BZ12,MATCH($D13,$AE$1:$BZ$1,0)),"") | L13: =IFERROR(INDEX($AE12:$BZ12,MATCH($E13,$AE$1:$BZ$1,0)),"") | M13: =IF(OR($K13="",$L13=""),"",($K13+100*$F13)-($L13+100*$G13)) | N13: =IF($M13="","",1/(1+10^(-$M13/400))) | O13: =IF(OR($H13=0,$N13=""),"",IF($I13>$J13,1,IF($I13=$J13,0.5,0))) | P13: =IF($O13="","",IF(ABS($I13-$J13)<=1,1,IF(ABS($I13-$J13)=2,1.5,IF(ABS($I13-$J13)=3,1.75,1.75+(ABS($I13-$J13)-3)/8)))) | Q13: =IF($O13="",0,Equipos!$O$4*$P13*($O13-$N13)) | R13: =IF($K13="","",$K13+$Q13) | S13: =IF($L13="","",$L13-$Q13) | T13: =IF($M13="","",Equipos!$O$3*$M13) | U13: =IFERROR(VLOOKUP($D13,Equipos!$A:$H,6,0),"") | V13: =IFERROR(VLOOKUP($D13,Equipos!$A:$H,7,0),"") | W13: =IFERROR(VLOOKUP($E13,Equipos!$A:$H,6,0),"") | X13: =IFERROR(VLOOKUP($E13,Equipos!$A:$H,7,0),"") | Y13: =IF(OR($U13="",$W13=""),"",MIN(3.6,MAX(1.8,Equipos!$O$2*SQRT($U13*$W13*$V13*$X13)))) | Z13: =IF(OR($Y13="",$T13=""),"",MAX(0.2,($Y13+$T13)/2)) | AA13: =IF(OR($Y13="",$T13=""),"",MAX(0.2,($Y13-$T13)/2)) | AE13: =IF($D13=AE$1,$R13,IF($E13=AE$1,$S13,AE12)) | AF13: =IF($D13=AF$1,$R13,IF($E13=AF$1,$S13,AF12)) | AG13: =IF($D13=AG$1,$R13,IF($E13=AG$1,$S13,AG12)) | AH13: =IF($D13=AH$1,$R13,IF($E13=AH$1,$S13,AH12)) | AI13: =IF($D13=AI$1,$R13,IF($E13=AI$1,$S13,AI12)) | AJ13: =IF($D13=AJ$1,$R13,IF($E13=AJ$1,$S13,AJ12)) | AK13: =IF($D13=AK$1,$R13,IF($E13=AK$1,$S13,AK12)) | AL13: =IF($D13=AL$1,$R13,IF($E13=AL$1,$S13,AL12)) | ... BZ13: =IF($D13=BZ$1,$R13,IF($E13=BZ$1,$S13,BZ12))
A14: =Fixture!A13 | B14: =Fixture!B13 | C14: =Fixture!C13 | D14: =Fixture!E13 | E14: =Fixture!F13 | F14: =Fixture!J13 | G14: =Fixture!K13 | H14: =IF(ISNUMBER(Resultados!B13),1,0) | I14: =IF($H14=1,Resultados!B13,0) | J14: =IF($H14=1,Resultados!C13,0) | K14: =IFERROR(INDEX($AE13:$BZ13,MATCH($D14,$AE$1:$BZ$1,0)),"") | L14: =IFERROR(INDEX($AE13:$BZ13,MATCH($E14,$AE$1:$BZ$1,0)),"") | M14: =IF(OR($K14="",$L14=""),"",($K14+100*$F14)-($L14+100*$G14)) | N14: =IF($M14="","",1/(1+10^(-$M14/400))) | O14: =IF(OR($H14=0,$N14=""),"",IF($I14>$J14,1,IF($I14=$J14,0.5,0))) | P14: =IF($O14="","",IF(ABS($I14-$J14)<=1,1,IF(ABS($I14-$J14)=2,1.5,IF(ABS($I14-$J14)=3,1.75,1.75+(ABS($I14-$J14)-3)/8)))) | Q14: =IF($O14="",0,Equipos!$O$4*$P14*($O14-$N14)) | R14: =IF($K14="","",$K14+$Q14) | S14: =IF($L14="","",$L14-$Q14) | T14: =IF($M14="","",Equipos!$O$3*$M14) | U14: =IFERROR(VLOOKUP($D14,Equipos!$A:$H,6,0),"") | V14: =IFERROR(VLOOKUP($D14,Equipos!$A:$H,7,0),"") | W14: =IFERROR(VLOOKUP($E14,Equipos!$A:$H,6,0),"") | X14: =IFERROR(VLOOKUP($E14,Equipos!$A:$H,7,0),"") | Y14: =IF(OR($U14="",$W14=""),"",MIN(3.6,MAX(1.8,Equipos!$O$2*SQRT($U14*$W14*$V14*$X14)))) | Z14: =IF(OR($Y14="",$T14=""),"",MAX(0.2,($Y14+$T14)/2)) | AA14: =IF(OR($Y14="",$T14=""),"",MAX(0.2,($Y14-$T14)/2)) | AE14: =IF($D14=AE$1,$R14,IF($E14=AE$1,$S14,AE13)) | AF14: =IF($D14=AF$1,$R14,IF($E14=AF$1,$S14,AF13)) | AG14: =IF($D14=AG$1,$R14,IF($E14=AG$1,$S14,AG13)) | AH14: =IF($D14=AH$1,$R14,IF($E14=AH$1,$S14,AH13)) | AI14: =IF($D14=AI$1,$R14,IF($E14=AI$1,$S14,AI13)) | AJ14: =IF($D14=AJ$1,$R14,IF($E14=AJ$1,$S14,AJ13)) | AK14: =IF($D14=AK$1,$R14,IF($E14=AK$1,$S14,AK13)) | AL14: =IF($D14=AL$1,$R14,IF($E14=AL$1,$S14,AL13)) | ... BZ14: =IF($D14=BZ$1,$R14,IF($E14=BZ$1,$S14,BZ13))
... A106: =Fixture!A105 | B106: =Fixture!B105 | C106: =Fixture!C105 | D106: =Fixture!E105 | E106: =Fixture!F105 | F106: =Fixture!J105 | G106: =Fixture!K105 | H106: =IF(ISNUMBER(Resultados!B105),1,0) | I106: =IF($H106=1,Resultados!B105,0) | J106: =IF($H106=1,Resultados!C105,0) | K106: =IFERROR(INDEX($AE105:$BZ105,MATCH($D106,$AE$1:$BZ$1,0)),"") | L106: =IFERROR(INDEX($AE105:$BZ105,MATCH($E106,$AE$1:$BZ$1,0)),"") | M106: =IF(OR($K106="",$L106=""),"",($K106+100*$F106)-($L106+100*$G106)) | N106: =IF($M106="","",1/(1+10^(-$M106/400))) | O106: =IF(OR($H106=0,$N106=""),"",IF($I106>$J106,1,IF($I106=$J106,0.5,0))) | P106: =IF($O106="","",IF(ABS($I106-$J106)<=1,1,IF(ABS($I106-$J106)=2,1.5,IF(ABS($I106-$J106)=3,1.75,1.75+(ABS($I106-$J106)-3)/8)))) | Q106: =IF($O106="",0,Equipos!$O$4*$P106*($O106-$N106)) | R106: =IF($K106="","",$K106+$Q106) | S106: =IF($L106="","",$L106-$Q106) | T106: =IF($M106="","",Equipos!$O$3*$M106) | U106: =IFERROR(VLOOKUP($D106,Equipos!$A:$H,6,0),"") | V106: =IFERROR(VLOOKUP($D106,Equipos!$A:$H,7,0),"") | W106: =IFERROR(VLOOKUP($E106,Equipos!$A:$H,6,0),"") | X106: =IFERROR(VLOOKUP($E106,Equipos!$A:$H,7,0),"") | Y106: =IF(OR($U106="",$W106=""),"",MIN(3.6,MAX(1.8,Equipos!$O$2*SQRT($U106*$W106*$V106*$X106)))) | Z106: =IF(OR($Y106="",$T106=""),"",MAX(0.2,($Y106+$T106)/2)) | AA106: =IF(OR($Y106="",$T106=""),"",MAX(0.2,($Y106-$T106)/2)) | AE106: =IF($D106=AE$1,$R106,IF($E106=AE$1,$S106,AE105)) | AF106: =IF($D106=AF$1,$R106,IF($E106=AF$1,$S106,AF105)) | AG106: =IF($D106=AG$1,$R106,IF($E106=AG$1,$S106,AG105)) | AH106: =IF($D106=AH$1,$R106,IF($E106=AH$1,$S106,AH105)) | AI106: =IF($D106=AI$1,$R106,IF($E106=AI$1,$S106,AI105)) | AJ106: =IF($D106=AJ$1,$R106,IF($E106=AJ$1,$S106,AJ105)) | AK106: =IF($D106=AK$1,$R106,IF($E106=AK$1,$S106,AK105)) | AL106: =IF($D106=AL$1,$R106,IF($E106=AL$1,$S106,AL105)) | ... BZ106: =IF($D106=BZ$1,$R106,IF($E106=BZ$1,$S106,BZ105))
A108: Solo lectura conceptual: nadie edita aquí. Grid AE:BZ = Elo encadenado (fila 2 = inicial; fila r = Elo tras el partido de la fila r). Elo pre-partido = fila anterior del grid.

Sheet Predicciones
A1: NOTA: probabilidades de un modelo Elo+Poisson calibrado con datos históricos; no incorpora lesiones, alineaciones ni clima, y en fútbol el favorito pierde con frecuencia. P(1X2) normalizadas sobre marcadores 0–5 (residuo >5 repartido proporcionalmente). Marcador más probable = moda de las Poisson.
A2: ID | B2: Fecha | C2: Fase | D2: Equipo_A | E2: Equipo_B | F2: P(Gana A) | G2: P(Empate) | H2: P(Gana B) | I2: Marcador_Mas_Probable | J2: P(Marcador) | K2: raw_pA (aux) | L2: raw_pE (aux) | M2: raw_pB (aux)
A3: =Modelo!A3 | B3: =Modelo!B3 | C3: =Modelo!C3 | D3: =Modelo!D3 | E3: =Modelo!E3 | F3: =IF($K3="","",$K3/($K3+$L3+$M3)) | G3: =IF($K3="","",$L3/($K3+$L3+$M3)) | H3: =IF($K3="","",$M3/($K3+$L3+$M3)) | I3: =IF($K3="","",INT(Modelo!$Z3)&"-"&INT(Modelo!$AA3)) | J3: =IF($K3="","",POISSON(INT(Modelo!$Z3),Modelo!$Z3,0)*POISSON(INT(Modelo!$AA3),Modelo!$AA3,0)) | K3: =IF(OR(Modelo!$H3=1,Modelo!$Z3=""),"",SUMPRODUCT(POISSON({1,2,3,4,5},Modelo!$Z3,0),POISSON({0,1,2,3,4},Modelo!$AA3,1))) | L3: =IF(OR(Modelo!$H3=1,Modelo!$Z3=""),"",SUMPRODUCT(POISSON({0,1,2,3,4,5},Modelo!$Z3,0),POISSON({0,1,2,3,4,5},Modelo!$AA3,0))) | M3: =IF(OR(Modelo!$H3=1,Modelo!$Z3=""),"",SUMPRODUCT(POISSON({1,2,3,4,5},Modelo!$AA3,0),POISSON({0,1,2,3,4},Modelo!$Z3,1)))
A4: =Modelo!A4 | B4: =Modelo!B4 | C4: =Modelo!C4 | D4: =Modelo!D4 | E4: =Modelo!E4 | F4: =IF($K4="","",$K4/($K4+$L4+$M4)) | G4: =IF($K4="","",$L4/($K4+$L4+$M4)) | H4: =IF($K4="","",$M4/($K4+$L4+$M4)) | I4: =IF($K4="","",INT(Modelo!$Z4)&"-"&INT(Modelo!$AA4)) | J4: =IF($K4="","",POISSON(INT(Modelo!$Z4),Modelo!$Z4,0)*POISSON(INT(Modelo!$AA4),Modelo!$AA4,0)) | K4: =IF(OR(Modelo!$H4=1,Modelo!$Z4=""),"",SUMPRODUCT(POISSON({1,2,3,4,5},Modelo!$Z4,0),POISSON({0,1,2,3,4},Modelo!$AA4,1))) | L4: =IF(OR(Modelo!$H4=1,Modelo!$Z4=""),"",SUMPRODUCT(POISSON({0,1,2,3,4,5},Modelo!$Z4,0),POISSON({0,1,2,3,4,5},Modelo!$AA4,0))) | M4: =IF(OR(Modelo!$H4=1,Modelo!$Z4=""),"",SUMPRODUCT(POISSON({1,2,3,4,5},Modelo!$AA4,0),POISSON({0,1,2,3,4},Modelo!$Z4,1)))
A5: =Modelo!A5 | B5: =Modelo!B5 | C5: =Modelo!C5 | D5: =Modelo!D5 | E5: =Modelo!E5 | F5: =IF($K5="","",$K5/($K5+$L5+$M5)) | G5: =IF($K5="","",$L5/($K5+$L5+$M5)) | H5: =IF($K5="","",$M5/($K5+$L5+$M5)) | I5: =IF($K5="","",INT(Modelo!$Z5)&"-"&INT(Modelo!$AA5)) | J5: =IF($K5="","",POISSON(INT(Modelo!$Z5),Modelo!$Z5,0)*POISSON(INT(Modelo!$AA5),Modelo!$AA5,0)) | K5: =IF(OR(Modelo!$H5=1,Modelo!$Z5=""),"",SUMPRODUCT(POISSON({1,2,3,4,5},Modelo!$Z5,0),POISSON({0,1,2,3,4},Modelo!$AA5,1))) | L5: =IF(OR(Modelo!$H5=1,Modelo!$Z5=""),"",SUMPRODUCT(POISSON({0,1,2,3,4,5},Modelo!$Z5,0),POISSON({0,1,2,3,4,5},Modelo!$AA5,0))) | M5: =IF(OR(Modelo!$H5=1,Modelo!$Z5=""),"",SUMPRODUCT(POISSON({1,2,3,4,5},Modelo!$AA5,0),POISSON({0,1,2,3,4},Modelo!$Z5,1)))
A6: =Modelo!A6 | B6: =Modelo!B6 | C6: =Modelo!C6 | D6: =Modelo!D6 | E6: =Modelo!E6 | F6: =IF($K6="","",$K6/($K6+$L6+$M6)) | G6: =IF($K6="","",$L6/($K6+$L6+$M6)) | H6: =IF($K6="","",$M6/($K6+$L6+$M6)) | I6: =IF($K6="","",INT(Modelo!$Z6)&"-"&INT(Modelo!$AA6)) | J6: =IF($K6="","",POISSON(INT(Modelo!$Z6),Modelo!$Z6,0)*POISSON(INT(Modelo!$AA6),Modelo!$AA6,0)) | K6: =IF(OR(Modelo!$H6=1,Modelo!$Z6=""),"",SUMPRODUCT(POISSON({1,2,3,4,5},Modelo!$Z6,0),POISSON({0,1,2,3,4},Modelo!$AA6,1))) | L6: =IF(OR(Modelo!$H6=1,Modelo!$Z6=""),"",SUMPRODUCT(POISSON({0,1,2,3,4,5},Modelo!$Z6,0),POISSON({0,1,2,3,4,5},Modelo!$AA6,0))) | M6: =IF(OR(Modelo!$H6=1,Modelo!$Z6=""),"",SUMPRODUCT(POISSON({1,2,3,4,5},Modelo!$AA6,0),POISSON({0,1,2,3,4},Modelo!$Z6,1)))
A7: =Modelo!A7 | B7: =Modelo!B7 | C7: =Modelo!C7 | D7: =Modelo!D7 | E7: =Modelo!E7 | F7: =IF($K7="","",$K7/($K7+$L7+$M7)) | G7: =IF($K7="","",$L7/($K7+$L7+$M7)) | H7: =IF($K7="","",$M7/($K7+$L7+$M7)) | I7: =IF($K7="","",INT(Modelo!$Z7)&"-"&INT(Modelo!$AA7)) | J7: =IF($K7="","",POISSON(INT(Modelo!$Z7),Modelo!$Z7,0)*POISSON(INT(Modelo!$AA7),Modelo!$AA7,0)) | K7: =IF(OR(Modelo!$H7=1,Modelo!$Z7=""),"",SUMPRODUCT(POISSON({1,2,3,4,5},Modelo!$Z7,0),POISSON({0,1,2,3,4},Modelo!$AA7,1))) | L7: =IF(OR(Modelo!$H7=1,Modelo!$Z7=""),"",SUMPRODUCT(POISSON({0,1,2,3,4,5},Modelo!$Z7,0),POISSON({0,1,2,3,4,5},Modelo!$AA7,0))) | M7: =IF(OR(Modelo!$H7=1,Modelo!$Z7=""),"",SUMPRODUCT(POISSON({1,2,3,4,5},Modelo!$AA7,0),POISSON({0,1,2,3,4},Modelo!$Z7,1)))
A8: =Modelo!A8 | B8: =Modelo!B8 | C8: =Modelo!C8 | D8: =Modelo!D8 | E8: =Modelo!E8 | F8: =IF($K8="","",$K8/($K8+$L8+$M8)) | G8: =IF($K8="","",$L8/($K8+$L8+$M8)) | H8: =IF($K8="","",$M8/($K8+$L8+$M8)) | I8: =IF($K8="","",INT(Modelo!$Z8)&"-"&INT(Modelo!$AA8)) | J8: =IF($K8="","",POISSON(INT(Modelo!$Z8),Modelo!$Z8,0)*POISSON(INT(Modelo!$AA8),Modelo!$AA8,0)) | K8: =IF(OR(Modelo!$H8=1,Modelo!$Z8=""),"",SUMPRODUCT(POISSON({1,2,3,4,5},Modelo!$Z8,0),POISSON({0,1,2,3,4},Modelo!$AA8,1))) | L8: =IF(OR(Modelo!$H8=1,Modelo!$Z8=""),"",SUMPRODUCT(POISSON({0,1,2,3,4,5},Modelo!$Z8,0),POISSON({0,1,2,3,4,5},Modelo!$AA8,0))) | M8: =IF(OR(Modelo!$H8=1,Modelo!$Z8=""),"",SUMPRODUCT(POISSON({1,2,3,4,5},Modelo!$AA8,0),POISSON({0,1,2,3,4},Modelo!$Z8,1)))
A9: =Modelo!A9 | B9: =Modelo!B9 | C9: =Modelo!C9 | D9: =Modelo!D9 | E9: =Modelo!E9 | F9: =IF($K9="","",$K9/($K9+$L9+$M9)) | G9: =IF($K9="","",$L9/($K9+$L9+$M9)) | H9: =IF($K9="","",$M9/($K9+$L9+$M9)) | I9: =IF($K9="","",INT(Modelo!$Z9)&"-"&INT(Modelo!$AA9)) | J9: =IF($K9="","",POISSON(INT(Modelo!$Z9),Modelo!$Z9,0)*POISSON(INT(Modelo!$AA9),Modelo!$AA9,0)) | K9: =IF(OR(Modelo!$H9=1,Modelo!$Z9=""),"",SUMPRODUCT(POISSON({1,2,3,4,5},Modelo!$Z9,0),POISSON({0,1,2,3,4},Modelo!$AA9,1))) | L9: =IF(OR(Modelo!$H9=1,Modelo!$Z9=""),"",SUMPRODUCT(POISSON({0,1,2,3,4,5},Modelo!$Z9,0),POISSON({0,1,2,3,4,5},Modelo!$AA9,0))) | M9: =IF(OR(Modelo!$H9=1,Modelo!$Z9=""),"",SUMPRODUCT(POISSON({1,2,3,4,5},Modelo!$AA9,0),POISSON({0,1,2,3,4},Modelo!$Z9,1)))
A10: =Modelo!A10 | B10: =Modelo!B10 | C10: =Modelo!C10 | D10: =Modelo!D10 | E10: =Modelo!E10 | F10: =IF($K10="","",$K10/($K10+$L10+$M10)) | G10: =IF($K10="","",$L10/($K10+$L10+$M10)) | H10: =IF($K10="","",$M10/($K10+$L10+$M10)) | I10: =IF($K10="","",INT(Modelo!$Z10)&"-"&INT(Modelo!$AA10)) | J10: =IF($K10="","",POISSON(INT(Modelo!$Z10),Modelo!$Z10,0)*POISSON(INT(Modelo!$AA10),Modelo!$AA10,0)) | K10: =IF(OR(Modelo!$H10=1,Modelo!$Z10=""),"",SUMPRODUCT(POISSON({1,2,3,4,5},Modelo!$Z10,0),POISSON({0,1,2,3,4},Modelo!$AA10,1))) | L10: =IF(OR(Modelo!$H10=1,Modelo!$Z10=""),"",SUMPRODUCT(POISSON({0,1,2,3,4,5},Modelo!$Z10,0),POISSON({0,1,2,3,4,5},Modelo!$AA10,0))) | M10: =IF(OR(Modelo!$H10=1,Modelo!$Z10=""),"",SUMPRODUCT(POISSON({1,2,3,4,5},Modelo!$AA10,0),POISSON({0,1,2,3,4},Modelo!$Z10,1)))
A11: =Modelo!A11 | B11: =Modelo!B11 | C11: =Modelo!C11 | D11: =Modelo!D11 | E11: =Modelo!E11 | F11: =IF($K11="","",$K11/($K11+$L11+$M11)) | G11: =IF($K11="","",$L11/($K11+$L11+$M11)) | H11: =IF($K11="","",$M11/($K11+$L11+$M11)) | I11: =IF($K11="","",INT(Modelo!$Z11)&"-"&INT(Modelo!$AA11)) | J11: =IF($K11="","",POISSON(INT(Modelo!$Z11),Modelo!$Z11,0)*POISSON(INT(Modelo!$AA11),Modelo!$AA11,0)) | K11: =IF(OR(Modelo!$H11=1,Modelo!$Z11=""),"",SUMPRODUCT(POISSON({1,2,3,4,5},Modelo!$Z11,0),POISSON({0,1,2,3,4},Modelo!$AA11,1))) | L11: =IF(OR(Modelo!$H11=1,Modelo!$Z11=""),"",SUMPRODUCT(POISSON({0,1,2,3,4,5},Modelo!$Z11,0),POISSON({0,1,2,3,4,5},Modelo!$AA11,0))) | M11: =IF(OR(Modelo!$H11=1,Modelo!$Z11=""),"",SUMPRODUCT(POISSON({1,2,3,4,5},Modelo!$AA11,0),POISSON({0,1,2,3,4},Modelo!$Z11,1)))
A12: =Modelo!A12 | B12: =Modelo!B12 | C12: =Modelo!C12 | D12: =Modelo!D12 | E12: =Modelo!E12 | F12: =IF($K12="","",$K12/($K12+$L12+$M12)) | G12: =IF($K12="","",$L12/($K12+$L12+$M12)) | H12: =IF($K12="","",$M12/($K12+$L12+$M12)) | I12: =IF($K12="","",INT(Modelo!$Z12)&"-"&INT(Modelo!$AA12)) | J12: =IF($K12="","",POISSON(INT(Modelo!$Z12),Modelo!$Z12,0)*POISSON(INT(Modelo!$AA12),Modelo!$AA12,0)) | K12: =IF(OR(Modelo!$H12=1,Modelo!$Z12=""),"",SUMPRODUCT(POISSON({1,2,3,4,5},Modelo!$Z12,0),POISSON({0,1,2,3,4},Modelo!$AA12,1))) | L12: =IF(OR(Modelo!$H12=1,Modelo!$Z12=""),"",SUMPRODUCT(POISSON({0,1,2,3,4,5},Modelo!$Z12,0),POISSON({0,1,2,3,4,5},Modelo!$AA12,0))) | M12: =IF(OR(Modelo!$H12=1,Modelo!$Z12=""),"",SUMPRODUCT(POISSON({1,2,3,4,5},Modelo!$AA12,0),POISSON({0,1,2,3,4},Modelo!$Z12,1)))
A13: =Modelo!A13 | B13: =Modelo!B13 | C13: =Modelo!C13 | D13: =Modelo!D13 | E13: =Modelo!E13 | F13: =IF($K13="","",$K13/($K13+$L13+$M13)) | G13: =IF($K13="","",$L13/($K13+$L13+$M13)) | H13: =IF($K13="","",$M13/($K13+$L13+$M13)) | I13: =IF($K13="","",INT(Modelo!$Z13)&"-"&INT(Modelo!$AA13)) | J13: =IF($K13="","",POISSON(INT(Modelo!$Z13),Modelo!$Z13,0)*POISSON(INT(Modelo!$AA13),Modelo!$AA13,0)) | K13: =IF(OR(Modelo!$H13=1,Modelo!$Z13=""),"",SUMPRODUCT(POISSON({1,2,3,4,5},Modelo!$Z13,0),POISSON({0,1,2,3,4},Modelo!$AA13,1))) | L13: =IF(OR(Modelo!$H13=1,Modelo!$Z13=""),"",SUMPRODUCT(POISSON({0,1,2,3,4,5},Modelo!$Z13,0),POISSON({0,1,2,3,4,5},Modelo!$AA13,0))) | M13: =IF(OR(Modelo!$H13=1,Modelo!$Z13=""),"",SUMPRODUCT(POISSON({1,2,3,4,5},Modelo!$AA13,0),POISSON({0,1,2,3,4},Modelo!$Z13,1)))
A14: =Modelo!A14 | B14: =Modelo!B14 | C14: =Modelo!C14 | D14: =Modelo!D14 | E14: =Modelo!E14 | F14: =IF($K14="","",$K14/($K14+$L14+$M14)) | G14: =IF($K14="","",$L14/($K14+$L14+$M14)) | H14: =IF($K14="","",$M14/($K14+$L14+$M14)) | I14: =IF($K14="","",INT(Modelo!$Z14)&"-"&INT(Modelo!$AA14)) | J14: =IF($K14="","",POISSON(INT(Modelo!$Z14),Modelo!$Z14,0)*POISSON(INT(Modelo!$AA14),Modelo!$AA14,0)) | K14: =IF(OR(Modelo!$H14=1,Modelo!$Z14=""),"",SUMPRODUCT(POISSON({1,2,3,4,5},Modelo!$Z14,0),POISSON({0,1,2,3,4},Modelo!$AA14,1))) | L14: =IF(OR(Modelo!$H14=1,Modelo!$Z14=""),"",SUMPRODUCT(POISSON({0,1,2,3,4,5},Modelo!$Z14,0),POISSON({0,1,2,3,4,5},Modelo!$AA14,0))) | M14: =IF(OR(Modelo!$H14=1,Modelo!$Z14=""),"",SUMPRODUCT(POISSON({1,2,3,4,5},Modelo!$AA14,0),POISSON({0,1,2,3,4},Modelo!$Z14,1)))
... A106: =Modelo!A106 | B106: =Modelo!B106 | C106: =Modelo!C106 | D106: =Modelo!D106 | E106: =Modelo!E106 | F106: =IF($K106="","",$K106/($K106+$L106+$M106)) | G106: =IF($K106="","",$L106/($K106+$L106+$M106)) | H106: =IF($K106="","",$M106/($K106+$L106+$M106)) | I106: =IF($K106="","",INT(Modelo!$Z106)&"-"&INT(Modelo!$AA106)) | J106: =IF($K106="","",POISSON(INT(Modelo!$Z106),Modelo!$Z106,0)*POISSON(INT(Modelo!$AA106),Modelo!$AA106,0)) | K106: =IF(OR(Modelo!$H106=1,Modelo!$Z106=""),"",SUMPRODUCT(POISSON({1,2,3,4,5},Modelo!$Z106,0),POISSON({0,1,2,3,4},Modelo!$AA106,1))) | L106: =IF(OR(Modelo!$H106=1,Modelo!$Z106=""),"",SUMPRODUCT(POISSON({0,1,2,3,4,5},Modelo!$Z106,0),POISSON({0,1,2,3,4,5},Modelo!$AA106,0))) | M106: =IF(OR(Modelo!$H106=1,Modelo!$Z106=""),"",SUMPRODUCT(POISSON({1,2,3,4,5},Modelo!$AA106,0),POISSON({0,1,2,3,4},Modelo!$Z106,1)))

Sheet Tablas
A1: TABLAS DE GRUPOS (en vivo desde Resultados) — Desempate implementado: Pts → DG → GF. Head-to-head y fair play NO automatizados: verificar manualmente ante empate exacto.
A3: GRUPO A
A4: Equipo | B4: PJ | C4: PG | D4: PE | E4: PP | F4: GF | G4: GC | H4: DG | I4: Pts | J4: Pos | K4: Score
A5: México | B5: =SUMPRODUCT((Modelo!$C$3:$C$106="Grupos")*((Modelo!$D$3:$D$106=$A5)+(Modelo!$E$3:$E$106=$A5))*Modelo!$H$3:$H$106) | C5: =SUMPRODUCT((Modelo!$C$3:$C$106="Grupos")*(Modelo!$D$3:$D$106=$A5)*Modelo!$H$3:$H$106*(Modelo!$I$3:$I$106>Modelo!$J$3:$J$106))+SUMPRODUCT((Modelo!$C$3:$C$106="Grupos")*(Modelo!$E$3:$E$106=$A5)*Modelo!$H$3:$H$106*(Modelo!$J$3:$J$106>Modelo!$I$3:$I$106)) | D5: =SUMPRODUCT((Modelo!$C$3:$C$106="Grupos")*((Modelo!$D$3:$D$106=$A5)+(Modelo!$E$3:$E$106=$A5))*Modelo!$H$3:$H$106*(Modelo!$I$3:$I$106=Modelo!$J$3:$J$106)) | E5: =$B5-$C5-$D5 | F5: =SUMPRODUCT((Modelo!$C$3:$C$106="Grupos")*(Modelo!$D$3:$D$106=$A5)*Modelo!$H$3:$H$106*Modelo!$I$3:$I$106)+SUMPRODUCT((Modelo!$C$3:$C$106="Grupos")*(Modelo!$E$3:$E$106=$A5)*Modelo!$H$3:$H$106*Modelo!$J$3:$J$106) | G5: =SUMPRODUCT((Modelo!$C$3:$C$106="Grupos")*(Modelo!$D$3:$D$106=$A5)*Modelo!$H$3:$H$106*Modelo!$J$3:$J$106)+SUMPRODUCT((Modelo!$C$3:$C$106="Grupos")*(Modelo!$E$3:$E$106=$A5)*Modelo!$H$3:$H$106*Modelo!$I$3:$I$106) | H5: =$F5-$G5 | I5: =3*$C5+$D5 | J5: =1+SUMPRODUCT(($K$5:$K$8>$K5)*1) | K5: =$I5*1000000+($H5+200)*1000+$F5
A6: Sudáfrica | B6: =SUMPRODUCT((Modelo!$C$3:$C$106="Grupos")*((Modelo!$D$3:$D$106=$A6)+(Modelo!$E$3:$E$106=$A6))*Modelo!$H$3:$H$106) | C6: =SUMPRODUCT((Modelo!$C$3:$C$106="Grupos")*(Modelo!$D$3:$D$106=$A6)*Modelo!$H$3:$H$106*(Modelo!$I$3:$I$106>Modelo!$J$3:$J$106))+SUMPRODUCT((Modelo!$C$3:$C$106="Grupos")*(Modelo!$E$3:$E$106=$A6)*Modelo!$H$3:$H$106*(Modelo!$J$3:$J$106>Modelo!$I$3:$I$106)) | D6: =SUMPRODUCT((Modelo!$C$3:$C$106="Grupos")*((Modelo!$D$3:$D$106=$A6)+(Modelo!$E$3:$E$106=$A6))*Modelo!$H$3:$H$106*(Modelo!$I$3:$I$106=Modelo!$J$3:$J$106)) | E6: =$B6-$C6-$D6 | F6: =SUMPRODUCT((Modelo!$C$3:$C$106="Grupos")*(Modelo!$D$3:$D$106=$A6)*Modelo!$H$3:$H$106*Modelo!$I$3:$I$106)+SUMPRODUCT((Modelo!$C$3:$C$106="Grupos")*(Modelo!$E$3:$E$106=$A6)*Modelo!$H$3:$H$106*Modelo!$J$3:$J$106) | G6: =SUMPRODUCT((Modelo!$C$3:$C$106="Grupos")*(Modelo!$D$3:$D$106=$A6)*Modelo!$H$3:$H$106*Modelo!$J$3:$J$106)+SUMPRODUCT((Modelo!$C$3:$C$106="Grupos")*(Modelo!$E$3:$E$106=$A6)*Modelo!$H$3:$H$106*Modelo!$I$3:$I$106) | H6: =$F6-$G6 | I6: =3*$C6+$D6 | J6: =1+SUMPRODUCT(($K$5:$K$8>$K6)*1) | K6: =$I6*1000000+($H6+200)*1000+$F6
A7: Corea del Sur | B7: =SUMPRODUCT((Modelo!$C$3:$C$106="Grupos")*((Modelo!$D$3:$D$106=$A7)+(Modelo!$E$3:$E$106=$A7))*Modelo!$H$3:$H$106) | C7: =SUMPRODUCT((Modelo!$C$3:$C$106="Grupos")*(Modelo!$D$3:$D$106=$A7)*Modelo!$H$3:$H$106*(Modelo!$I$3:$I$106>Modelo!$J$3:$J$106))+SUMPRODUCT((Modelo!$C$3:$C$106="Grupos")*(Modelo!$E$3:$E$106=$A7)*Modelo!$H$3:$H$106*(Modelo!$J$3:$J$106>Modelo!$I$3:$I$106)) | D7: =SUMPRODUCT((Modelo!$C$3:$C$106="Grupos")*((Modelo!$D$3:$D$106=$A7)+(Modelo!$E$3:$E$106=$A7))*Modelo!$H$3:$H$106*(Modelo!$I$3:$I$106=Modelo!$J$3:$J$106)) | E7: =$B7-$C7-$D7 | F7: =SUMPRODUCT((Modelo!$C$3:$C$106="Grupos")*(Modelo!$D$3:$D$106=$A7)*Modelo!$H$3:$H$106*Modelo!$I$3:$I$106)+SUMPRODUCT((Modelo!$C$3:$C$106="Grupos")*(Modelo!$E$3:$E$106=$A7)*Modelo!$H$3:$H$106*Modelo!$J$3:$J$106) | G7: =SUMPRODUCT((Modelo!$C$3:$C$106="Grupos")*(Modelo!$D$3:$D$106=$A7)*Modelo!$H$3:$H$106*Modelo!$J$3:$J$106)+SUMPRODUCT((Modelo!$C$3:$C$106="Grupos")*(Modelo!$E$3:$E$106=$A7)*Modelo!$H$3:$H$106*Modelo!$I$3:$I$106) | H7: =$F7-$G7 | I7: =3*$C7+$D7 | J7: =1+SUMPRODUCT(($K$5:$K$8>$K7)*1) | K7: =$I7*1000000+($H7+200)*1000+$F7
A8: Chequia | B8: =SUMPRODUCT((Modelo!$C$3:$C$106="Grupos")*((Modelo!$D$3:$D$106=$A8)+(Modelo!$E$3:$E$106=$A8))*Modelo!$H$3:$H$106) | C8: =SUMPRODUCT((Modelo!$C$3:$C$106="Grupos")*(Modelo!$D$3:$D$106=$A8)*Modelo!$H$3:$H$106*(Modelo!$I$3:$I$106>Modelo!$J$3:$J$106))+SUMPRODUCT((Modelo!$C$3:$C$106="Grupos")*(Modelo!$E$3:$E$106=$A8)*Modelo!$H$3:$H$106*(Modelo!$J$3:$J$106>Modelo!$I$3:$I$106)) | D8: =SUMPRODUCT((Modelo!$C$3:$C$106="Grupos")*((Modelo!$D$3:$D$106=$A8)+(Modelo!$E$3:$E$106=$A8))*Modelo!$H$3:$H$106*(Modelo!$I$3:$I$106=Modelo!$J$3:$J$106)) | E8: =$B8-$C8-$D8 | F8: =SUMPRODUCT((Modelo!$C$3:$C$106="Grupos")*(Modelo!$D$3:$D$106=$A8)*Modelo!$H$3:$H$106*Modelo!$I$3:$I$106)+SUMPRODUCT((Modelo!$C$3:$C$106="Grupos")*(Modelo!$E$3:$E$106=$A8)*Modelo!$H$3:$H$106*Modelo!$J$3:$J$106) | G8: =SUMPRODUCT((Modelo!$C$3:$C$106="Grupos")*(Modelo!$D$3:$D$106=$A8)*Modelo!$H$3:$H$106*Modelo!$J$3:$J$106)+SUMPRODUCT((Modelo!$C$3:$C$106="Grupos")*(Modelo!$E$3:$E$106=$A8)*Modelo!$H$3:$H$106*Modelo!$I$3:$I$106) | H8: =$F8-$G8 | I8: =3*$C8+$D8 | J8: =1+SUMPRODUCT(($K$5:$K$8>$K8)*1) | K8: =$I8*1000000+($H8+200)*1000+$F8
A10: GRUPO B
A11: Equipo | B11: PJ | C11: PG | D11: PE | E11: PP | F11: GF | G11: GC | H11: DG | I11: Pts | J11: Pos | K11: Score
